2025-01-08 15:28:30,971 - ERROR - Ignoring exception in command None
discord.ext.commands.errors.CommandNotFound: Command ".." is not found
2025-01-08 15:39:16,518 - ERROR - Ignoring exception in command None
discord.ext.commands.errors.CommandNotFound: Command ".." is not found
2025-01-08 15:39:16,530 - ERROR - Ignoring exception in command None
discord.ext.commands.errors.CommandNotFound: Command ".." is not found
2025-01-08 15:40:46,330 - ERROR - Ignoring exception in command None
discord.ext.commands.errors.CommandNotFound: Command "." is not found
2025-01-08 16:44:15,561 - INFO - Shard ID None has successfully RESUMED session 2d9d9c059dd71b54341da9f543363664.
2025-01-08 17:02:49,482 - WARNING - Can't keep up, shard ID None websocket is 41.4s behind.
2025-01-08 17:48:48,759 - ERROR - Ignoring exception in command None
discord.ext.commands.errors.CommandNotFound: Command ".." is not found
2025-01-08 17:48:49,493 - ERROR - Ignoring exception in command None
discord.ext.commands.errors.CommandNotFound: Command ".." is not found
2025-01-08 17:50:05,253 - ERROR - Ignoring exception in command None
discord.ext.commands.errors.CommandNotFound: Command "...." is not found
2025-01-08 17:50:06,699 - ERROR - Ignoring exception in command None
discord.ext.commands.errors.CommandNotFound: Command "...." is not found
2025-01-08 17:53:07,818 - ERROR - Ignoring exception in command None
discord.ext.commands.errors.CommandNotFound: Command ".." is not found
2025-01-08 17:53:10,054 - ERROR - Ignoring exception in command None
discord.ext.commands.errors.CommandNotFound: Command ".." is not found
2025-01-08 18:02:34,358 - ERROR - Ignoring exception in command None
discord.ext.commands.errors.CommandNotFound: Command "..." is not found
2025-01-08 18:02:34,360 - ERROR - Ignoring exception in command None
discord.ext.commands.errors.CommandNotFound: Command "..." is not found
2025-01-08 18:03:39,789 - ERROR - Ignoring exception in command None
discord.ext.commands.errors.CommandNotFound: Command "..." is not found
2025-01-08 18:03:39,791 - ERROR - Ignoring exception in command None
discord.ext.commands.errors.CommandNotFound: Command "..." is not found
2025-01-08 18:13:57,231 - ERROR - Ignoring exception in command None
discord.ext.commands.errors.CommandNotFound: Command "..." is not found
2025-01-08 18:13:57,234 - ERROR - Ignoring exception in command None
discord.ext.commands.errors.CommandNotFound: Command "..." is not found
2025-01-08 18:14:35,002 - ERROR - Ignoring exception in command None
discord.ext.commands.errors.CommandNotFound: Command ".." is not found
2025-01-08 18:14:35,083 - ERROR - Ignoring exception in command None
discord.ext.commands.errors.CommandNotFound: Command ".." is not found
2025-01-08 18:19:20,156 - ERROR - Ignoring exception in command None
discord.ext.commands.errors.CommandNotFound: Command ".." is not found
2025-01-08 18:19:20,157 - ERROR - Ignoring exception in command None
discord.ext.commands.errors.CommandNotFound: Command ".." is not found
2025-01-08 18:19:35,902 - ERROR - Ignoring exception in command None
discord.ext.commands.errors.CommandNotFound: Command "......" is not found
2025-01-08 18:19:35,907 - ERROR - Ignoring exception in command None
discord.ext.commands.errors.CommandNotFound: Command "......" is not found
2025-01-08 18:25:49,566 - ERROR - Ignoring exception in command None
discord.ext.commands.errors.CommandNotFound: Command ".." is not found
2025-01-08 18:25:49,568 - ERROR - Ignoring exception in command None
discord.ext.commands.errors.CommandNotFound: Command ".." is not found
2025-01-08 18:26:56,575 - ERROR - Ignoring exception in command None
discord.ext.commands.errors.CommandNotFound: Command ".." is not found
2025-01-08 18:26:56,577 - ERROR - Ignoring exception in command None
discord.ext.commands.errors.CommandNotFound: Command ".." is not found
2025-01-08 18:35:45,712 - ERROR - Ignoring exception in command None
discord.ext.commands.errors.CommandNotFound: Command "..." is not found
2025-01-08 18:35:45,716 - ERROR - Ignoring exception in command None
discord.ext.commands.errors.CommandNotFound: Command "..." is not found
2025-01-08 18:36:54,317 - ERROR - Ignoring exception in command None
discord.ext.commands.errors.CommandNotFound: Command "..idk" is not found
2025-01-08 18:36:54,319 - ERROR - Ignoring exception in command None
discord.ext.commands.errors.CommandNotFound: Command "..idk" is not found
2025-01-08 18:38:23,449 - ERROR - Ignoring exception in command None
discord.ext.commands.errors.CommandNotFound: Command "...i" is not found
2025-01-08 18:38:23,451 - ERROR - Ignoring exception in command None
discord.ext.commands.errors.CommandNotFound: Command "...i" is not found
2025-01-08 18:38:34,136 - ERROR - Ignoring exception in command None
discord.ext.commands.errors.CommandNotFound: Command "..." is not found
2025-01-08 18:38:34,140 - ERROR - Ignoring exception in command None
discord.ext.commands.errors.CommandNotFound: Command "..." is not found
2025-01-08 19:25:24,634 - ERROR - Ignoring exception in command None
discord.ext.commands.errors.CommandNotFound: Command ".../ᐠ｡ꞈ｡ᐟ\" is not found
2025-01-08 20:14:33,050 - ERROR - Ignoring exception in command None
discord.ext.commands.errors.CommandNotFound: Command ".." is not found
2025-01-08 20:14:33,076 - ERROR - Ignoring exception in command None
discord.ext.commands.errors.CommandNotFound: Command ".." is not found
2025-01-08 20:32:42,754 - INFO - Shard ID None has successfully RESUMED session 2d9d9c059dd71b54341da9f543363664.
2025-01-08 21:01:21,920 - ERROR - Ignoring exception in command None
discord.ext.commands.errors.CommandNotFound: Command "staff" is not found
2025-01-08 21:01:22,546 - ERROR - Ignoring exception in command None
discord.ext.commands.errors.CommandNotFound: Command "staff" is not found
2025-01-08 21:18:43,989 - ERROR - Ignoring exception in command None
discord.ext.commands.errors.CommandNotFound: Command "voice" is not found
2025-01-08 21:53:16,455 - ERROR - Ignoring exception in command None
discord.ext.commands.errors.CommandNotFound: Command ".." is not found
2025-01-08 22:04:31,300 - INFO - Shard ID None has successfully RESUMED session 2d9d9c059dd71b54341da9f543363664.
2025-01-09 00:13:27,028 - ERROR - Ignoring exception in command None
discord.ext.commands.errors.CommandNotFound: Command ".." is not found
2025-01-09 00:13:27,037 - ERROR - Ignoring exception in command None
discord.ext.commands.errors.CommandNotFound: Command ".." is not found
2025-01-09 00:24:35,763 - INFO - Shard ID None has successfully RESUMED session 2d9d9c059dd71b54341da9f543363664.
2025-01-09 01:44:26,489 - INFO - Shard ID None has successfully RESUMED session 2d9d9c059dd71b54341da9f543363664.
2025-01-09 02:09:31,940 - INFO - Shard ID None has successfully RESUMED session 2d9d9c059dd71b54341da9f543363664.
2025-01-09 02:45:59,341 - ERROR - Ignoring exception in command None
discord.ext.commands.errors.CommandNotFound: Command "play" is not found
2025-01-09 04:14:28,364 - INFO - Shard ID None has successfully RESUMED session 2d9d9c059dd71b54341da9f543363664.
2025-01-09 05:15:17,287 - ERROR - Ignoring exception in command None
discord.ext.commands.errors.CommandNotFound: Command "..what" is not found
2025-01-09 05:15:17,288 - ERROR - Ignoring exception in command None
discord.ext.commands.errors.CommandNotFound: Command "..what" is not found
2025-01-09 06:05:11,024 - INFO - Shard ID None has successfully RESUMED session 2d9d9c059dd71b54341da9f543363664.
2025-01-09 07:19:15,745 - ERROR - Ignoring exception in command None
discord.ext.commands.errors.CommandNotFound: Command "ban" is not found
2025-01-09 07:19:15,746 - ERROR - Ignoring exception in command None
discord.ext.commands.errors.CommandNotFound: Command "ban" is not found
2025-01-09 07:28:10,331 - INFO - Shard ID None has successfully RESUMED session 2d9d9c059dd71b54341da9f543363664.
2025-01-09 08:52:56,533 - INFO - Shard ID None has successfully RESUMED session 2d9d9c059dd71b54341da9f543363664.
2025-01-09 09:34:37,981 - ERROR - Ignoring exception in command None
discord.ext.commands.errors.CommandNotFound: Command "artist" is not found
2025-01-09 10:33:39,727 - ERROR - Ignoring exception in command None
discord.ext.commands.errors.CommandNotFound: Command "." is not found
2025-01-09 10:33:39,732 - ERROR - Ignoring exception in command None
discord.ext.commands.errors.CommandNotFound: Command "." is not found
2025-01-09 10:56:48,124 - ERROR - Ignoring exception in command None
discord.ext.commands.errors.CommandNotFound: Command "." is not found
2025-01-09 10:56:48,322 - ERROR - Ignoring exception in command None
discord.ext.commands.errors.CommandNotFound: Command "." is not found
2025-01-09 11:33:49,854 - INFO - Shard ID None has successfully RESUMED session 2d9d9c059dd71b54341da9f543363664.
2025-01-09 11:34:23,733 - ERROR - Ignoring exception in command None
discord.ext.commands.errors.CommandNotFound: Command ".." is not found
2025-01-09 11:42:46,466 - ERROR - Ignoring exception in command None
discord.ext.commands.errors.CommandNotFound: Command "." is not found
2025-01-09 12:33:22,907 - INFO - Shard ID None has successfully RESUMED session 2d9d9c059dd71b54341da9f543363664.
2025-01-09 13:17:29,678 - INFO - Shard ID None has successfully RESUMED session 2d9d9c059dd71b54341da9f543363664.
2025-01-09 13:28:43,139 - ERROR - Ignoring exception in command None
discord.ext.commands.errors.CommandNotFound: Command ".." is not found
2025-01-09 13:32:40,410 - ERROR - Attempting a reconnect in 1.15s
Traceback (most recent call last):
  File "/home/container/.local/lib/python3.12/site-packages/aiohttp/connector.py", line 1351, in _create_direct_connection
    hosts = await self._resolve_host(host, port, traces=traces)
            ^^^^^^^^^^^^^^^^^^^^^^^^^^^^^^^^^^^^^^^^^^^^^^^^^^^
  File "/home/container/.local/lib/python3.12/site-packages/aiohttp/connector.py", line 995, in _resolve_host
    return await asyncio.shield(resolved_host_task)
           ^^^^^^^^^^^^^^^^^^^^^^^^^^^^^^^^^^^^^^^^
  File "/home/container/.local/lib/python3.12/site-packages/aiohttp/connector.py", line 1026, in _resolve_host_with_throttle
    addrs = await self._resolver.resolve(host, port, family=self._family)
            ^^^^^^^^^^^^^^^^^^^^^^^^^^^^^^^^^^^^^^^^^^^^^^^^^^^^^^^^^^^^^
  File "/home/container/.local/lib/python3.12/site-packages/aiohttp/resolver.py", line 36, in resolve
    infos = await self._loop.getaddrinfo(
            ^^^^^^^^^^^^^^^^^^^^^^^^^^^^^
  File "/usr/local/lib/python3.12/asyncio/base_events.py", line 900, in getaddrinfo
    return await self.run_in_executor(
           ^^^^^^^^^^^^^^^^^^^^^^^^^^^
  File "/usr/local/lib/python3.12/concurrent/futures/thread.py", line 59, in run
    result = self.fn(*self.args, **self.kwargs)
             ^^^^^^^^^^^^^^^^^^^^^^^^^^^^^^^^^^
  File "/usr/local/lib/python3.12/socket.py", line 976, in getaddrinfo
    for res in _socket.getaddrinfo(host, port, family, type, proto, flags):
               ^^^^^^^^^^^^^^^^^^^^^^^^^^^^^^^^^^^^^^^^^^^^^^^^^^^^^^^^^^^
socket.gaierror: [Errno -3] Temporary failure in name resolution

The above exception was the direct cause of the following exception:

Traceback (most recent call last):
  File "/home/container/.local/lib/python3.12/site-packages/discord/client.py", line 664, in connect
    self.ws = await asyncio.wait_for(coro, timeout=60.0)
              ^^^^^^^^^^^^^^^^^^^^^^^^^^^^^^^^^^^^^^^^^^
  File "/usr/local/lib/python3.12/asyncio/tasks.py", line 520, in wait_for
    return await fut
           ^^^^^^^^^
  File "/home/container/.local/lib/python3.12/site-packages/discord/gateway.py", line 374, in from_client
    socket = await client.http.ws_connect(str(url))
             ^^^^^^^^^^^^^^^^^^^^^^^^^^^^^^^^^^^^^^
  File "/home/container/.local/lib/python3.12/site-packages/discord/http.py", line 550, in ws_connect
    return await self.__session.ws_connect(url, **kwargs)
           ^^^^^^^^^^^^^^^^^^^^^^^^^^^^^^^^^^^^^^^^^^^^^^
  File "/home/container/.local/lib/python3.12/site-packages/aiohttp/client.py", line 1004, in _ws_connect
    resp = await self.request(
           ^^^^^^^^^^^^^^^^^^^
  File "/home/container/.local/lib/python3.12/site-packages/aiohttp/client.py", line 703, in _request
    conn = await self._connector.connect(
           ^^^^^^^^^^^^^^^^^^^^^^^^^^^^^^
  File "/home/container/.local/lib/python3.12/site-packages/aiohttp/connector.py", line 548, in connect
    proto = await self._create_connection(req, traces, timeout)
            ^^^^^^^^^^^^^^^^^^^^^^^^^^^^^^^^^^^^^^^^^^^^^^^^^^^
  File "/home/container/.local/lib/python3.12/site-packages/aiohttp/connector.py", line 1056, in _create_connection
    _, proto = await self._create_direct_connection(req, traces, timeout)
               ^^^^^^^^^^^^^^^^^^^^^^^^^^^^^^^^^^^^^^^^^^^^^^^^^^^^^^^^^^
  File "/home/container/.local/lib/python3.12/site-packages/aiohttp/connector.py", line 1357, in _create_direct_connection
    raise ClientConnectorDNSError(req.connection_key, exc) from exc
aiohttp.client_exceptions.ClientConnectorDNSError: Cannot connect to host gateway-us-east1-d.discord.gg:443 ssl:default [Temporary failure in name resolution]
2025-01-09 13:32:49,575 - INFO - Shard ID None has successfully RESUMED session 2d9d9c059dd71b54341da9f543363664.
2025-01-09 14:09:32,564 - ERROR - Ignoring exception in command None
discord.ext.commands.errors.CommandNotFound: Command "..." is not found
2025-01-09 14:09:32,566 - ERROR - Ignoring exception in command None
discord.ext.commands.errors.CommandNotFound: Command "..." is not found
2025-01-09 14:25:21,296 - WARNING - Can't keep up, shard ID None websocket is 58.2s behind.
2025-01-09 14:38:04,619 - ERROR - Attempting a reconnect in 1.27s
Traceback (most recent call last):
  File "/home/container/.local/lib/python3.12/site-packages/discord/client.py", line 667, in connect
    await self.ws.poll_event()
  File "/home/container/.local/lib/python3.12/site-packages/discord/gateway.py", line 648, in poll_event
    raise ConnectionClosed(self.socket, shard_id=self.shard_id, code=code) from None
discord.errors.ConnectionClosed: Shard ID None WebSocket closed with 1000
2025-01-09 14:38:09,847 - INFO - Shard ID None has successfully RESUMED session 2d9d9c059dd71b54341da9f543363664.
2025-01-09 15:00:41,667 - ERROR - Ignoring exception in command None
discord.ext.commands.errors.CommandNotFound: Command "-." is not found
2025-01-09 15:00:41,669 - ERROR - Ignoring exception in command None
discord.ext.commands.errors.CommandNotFound: Command "-." is not found
2025-01-09 15:04:34,888 - ERROR - Ignoring exception in command None
discord.ext.commands.errors.CommandNotFound: Command "." is not found
2025-01-09 15:15:33,980 - ERROR - Ignoring exception in command None
discord.ext.commands.errors.CommandNotFound: Command "...." is not found
2025-01-09 15:15:34,113 - ERROR - Ignoring exception in command None
discord.ext.commands.errors.CommandNotFound: Command "...." is not found
2025-01-09 15:40:13,232 - ERROR - Ignoring exception in command None
discord.ext.commands.errors.CommandNotFound: Command "...." is not found
2025-01-09 15:40:13,233 - ERROR - Ignoring exception in command None
discord.ext.commands.errors.CommandNotFound: Command "...." is not found
2025-01-09 15:58:38,789 - INFO - Shard ID None has successfully RESUMED session 2d9d9c059dd71b54341da9f543363664.
2025-01-09 16:32:43,707 - INFO - Shard ID None has successfully RESUMED session 2d9d9c059dd71b54341da9f543363664.
2025-01-09 16:42:58,602 - ERROR - Ignoring exception in command None
discord.ext.commands.errors.CommandNotFound: Command ".../ᐠ｡ꞈ｡ᐟ\" is not found
2025-01-09 16:50:15,920 - INFO - Shard ID None has successfully RESUMED session 2d9d9c059dd71b54341da9f543363664.
2025-01-09 16:57:20,449 - ERROR - Ignoring exception in command None
discord.ext.commands.errors.CommandNotFound: Command "...TF" is not found
2025-01-09 16:57:20,495 - ERROR - Ignoring exception in command None
discord.ext.commands.errors.CommandNotFound: Command "...TF" is not found
2025-01-09 17:01:59,638 - INFO - Shard ID None has successfully RESUMED session 2d9d9c059dd71b54341da9f543363664.
2025-01-09 17:27:27,292 - ERROR - Ignoring exception in command None
discord.ext.commands.errors.CommandNotFound: Command "........." is not found
2025-01-09 17:27:27,302 - ERROR - Ignoring exception in command None
discord.ext.commands.errors.CommandNotFound: Command "........." is not found
2025-01-09 17:33:06,842 - INFO - Shard ID None has successfully RESUMED session 2d9d9c059dd71b54341da9f543363664.
2025-01-09 18:10:18,754 - INFO - Shard ID None has successfully RESUMED session 2d9d9c059dd71b54341da9f543363664.
2025-01-09 18:27:40,185 - ERROR - Ignoring exception in command None
discord.ext.commands.errors.CommandNotFound: Command "..." is not found
2025-01-09 19:22:33,298 - ERROR - Ignoring exception in command None
discord.ext.commands.errors.CommandNotFound: Command "." is not found
2025-01-09 19:35:49,154 - ERROR - Ignoring exception in command None
discord.ext.commands.errors.CommandNotFound: Command "play" is not found
2025-01-09 20:17:55,547 - ERROR - Ignoring exception in command None
discord.ext.commands.errors.CommandNotFound: Command "play" is not found
2025-01-09 20:28:56,274 - ERROR - Ignoring exception in command None
discord.ext.commands.errors.CommandNotFound: Command "................................................................................................................" is not found
2025-01-09 20:38:04,824 - INFO - Shard ID None has successfully RESUMED session 2d9d9c059dd71b54341da9f543363664.
2025-01-09 20:53:21,477 - ERROR - Ignoring exception in command None
discord.ext.commands.errors.CommandNotFound: Command "." is not found
2025-01-09 20:53:22,466 - ERROR - Ignoring exception in command None
discord.ext.commands.errors.CommandNotFound: Command "." is not found
2025-01-09 21:04:46,706 - INFO - Shard ID None has successfully RESUMED session 2d9d9c059dd71b54341da9f543363664.
2025-01-09 21:11:18,889 - ERROR - Ignoring exception in command None
discord.ext.commands.errors.CommandNotFound: Command "+" is not found
2025-01-09 21:11:18,963 - ERROR - Ignoring exception in command None
discord.ext.commands.errors.CommandNotFound: Command "+" is not found
2025-01-09 21:27:27,088 - ERROR - Ignoring exception in command None
discord.ext.commands.errors.CommandNotFound: Command "." is not found
2025-01-09 22:15:36,267 - ERROR - Ignoring exception in command None
discord.ext.commands.errors.CommandNotFound: Command "!?" is not found
2025-01-10 00:13:10,460 - INFO - Shard ID None has successfully RESUMED session 2d9d9c059dd71b54341da9f543363664.
2025-01-10 02:20:01,020 - INFO - Shard ID None has successfully RESUMED session 2d9d9c059dd71b54341da9f543363664.
2025-01-10 02:31:00,466 - ERROR - Ignoring exception in on_message
Traceback (most recent call last):
  File "/home/container/.local/lib/python3.12/site-packages/discord/client.py", line 449, in _run_event
    await coro(*args, **kwargs)
  File "/home/container/cogs/thread.py", line 55, in on_message
    thread = await message.create_thread(name=thread_name, auto_archive_duration=1440)
             ^^^^^^^^^^^^^^^^^^^^^^^^^^^^^^^^^^^^^^^^^^^^^^^^^^^^^^^^^^^^^^^^^^^^^^^^^
  File "/home/container/.local/lib/python3.12/site-packages/discord/message.py", line 1407, in create_thread
    data = await self._state.http.start_thread_with_message(
           ^^^^^^^^^^^^^^^^^^^^^^^^^^^^^^^^^^^^^^^^^^^^^^^^^
  File "/home/container/.local/lib/python3.12/site-packages/discord/http.py", line 758, in request
    raise HTTPException(response, data)
discord.errors.HTTPException: 400 Bad Request (error code: 10008): Unknown Message
2025-01-10 03:02:54,740 - WARNING - Can't keep up, shard ID None websocket is 57.0s behind.
2025-01-10 03:03:00,867 - WARNING - Can't keep up, shard ID None websocket is 63.2s behind.
2025-01-10 03:03:01,706 - WARNING - Shard ID None heartbeat blocked for more than 10 seconds.
Loop thread traceback (most recent call last):
  File "/home/container/main.py", line 86, in <module>
    bot.run(DISCORD_TOKEN)
  File "/home/container/.local/lib/python3.12/site-packages/discord/client.py", line 869, in run
    asyncio.run(runner())
  File "/usr/local/lib/python3.12/asyncio/runners.py", line 194, in run
    return runner.run(main)
  File "/usr/local/lib/python3.12/asyncio/runners.py", line 118, in run
    return self._loop.run_until_complete(task)
  File "/usr/local/lib/python3.12/asyncio/base_events.py", line 673, in run_until_complete
    self.run_forever()
  File "/usr/local/lib/python3.12/asyncio/base_events.py", line 640, in run_forever
    self._run_once()
  File "/usr/local/lib/python3.12/asyncio/base_events.py", line 1993, in _run_once
    handle = None  # Needed to break cycles when an exception occurs.
  File "/usr/local/lib/python3.12/asyncio/events.py", line 88, in _run
    self._context.run(self._callback, *self._args)
  File "/home/container/.local/lib/python3.12/site-packages/discord/ext/tasks/__init__.py", line 241, in _loop
    await self.coro(*args, **kwargs)
  File "/home/container/cogs/sticky.py", line 151, in sticky_task
    logging.error("Sticky task is running.")
  File "/usr/local/lib/python3.12/logging/__init__.py", line 2183, in error
    root.error(msg, *args, **kwargs)
  File "/usr/local/lib/python3.12/logging/__init__.py", line 1568, in error
    self._log(ERROR, msg, args, **kwargs)
  File "/usr/local/lib/python3.12/logging/__init__.py", line 1684, in _log
    self.handle(record)
  File "/usr/local/lib/python3.12/logging/__init__.py", line 1700, in handle
    self.callHandlers(record)
  File "/usr/local/lib/python3.12/logging/__init__.py", line 1762, in callHandlers
    hdlr.handle(record)
  File "/usr/local/lib/python3.12/logging/__init__.py", line 1028, in handle
    self.emit(record)
  File "/usr/local/lib/python3.12/logging/__init__.py", line 1280, in emit
    StreamHandler.emit(self, record)
  File "/usr/local/lib/python3.12/logging/__init__.py", line 1164, in emit
    self.flush()
  File "/usr/local/lib/python3.12/logging/__init__.py", line 1144, in flush
    self.stream.flush()

2025-01-10 03:03:40,273 - WARNING - Can't keep up, shard ID None websocket is 37.5s behind.
2025-01-10 03:04:25,556 - WARNING - Can't keep up, shard ID None websocket is 41.5s behind.
2025-01-10 03:59:50,526 - INFO - Shard ID None has successfully RESUMED session 2d9d9c059dd71b54341da9f543363664.
2025-01-10 04:48:34,650 - INFO - Shard ID None has successfully RESUMED session 2d9d9c059dd71b54341da9f543363664.
2025-01-10 05:17:00,898 - ERROR - Ignoring exception in command None
discord.ext.commands.errors.CommandNotFound: Command "_." is not found
2025-01-10 06:16:58,207 - WARNING - Can't keep up, shard ID None websocket is 50.8s behind.
2025-01-10 06:17:37,143 - WARNING - Can't keep up, shard ID None websocket is 38.9s behind.
2025-01-10 06:41:41,328 - WARNING - Can't keep up, shard ID None websocket is 42.8s behind.
2025-01-10 06:44:27,612 - WARNING - Can't keep up, shard ID None websocket is 42.5s behind.
2025-01-10 07:14:46,936 - ERROR - Ignoring exception in command None
discord.ext.commands.errors.CommandNotFound: Command "." is not found
2025-01-10 07:14:47,965 - ERROR - Ignoring exception in command None
discord.ext.commands.errors.CommandNotFound: Command ".." is not found
2025-01-10 07:14:49,310 - ERROR - Ignoring exception in command None
discord.ext.commands.errors.CommandNotFound: Command "..." is not found
2025-01-10 07:45:43,892 - WARNING - Can't keep up, shard ID None websocket is 41.9s behind.
2025-01-10 07:47:50,207 - ERROR - Attempting a reconnect in 0.19s
Traceback (most recent call last):
  File "/home/container/.local/lib/python3.12/site-packages/discord/client.py", line 667, in connect
    await self.ws.poll_event()
  File "/home/container/.local/lib/python3.12/site-packages/discord/gateway.py", line 625, in poll_event
    await self.received_message(msg.data)
  File "/home/container/.local/lib/python3.12/site-packages/discord/gateway.py", line 533, in received_message
    await self.send_as_json(beat)
  File "/home/container/.local/lib/python3.12/site-packages/discord/gateway.py", line 661, in send_as_json
    await self.send(utils._to_json(data))
  File "/home/container/.local/lib/python3.12/site-packages/discord/gateway.py", line 657, in send
    await self.socket.send_str(data)
  File "/home/container/.local/lib/python3.12/site-packages/aiohttp/client_ws.py", line 243, in send_str
    await self._writer.send_frame(
  File "/home/container/.local/lib/python3.12/site-packages/aiohttp/_websocket/writer.py", line 125, in send_frame
    raise ClientConnectionResetError("Cannot write to closing transport")
aiohttp.client_exceptions.ClientConnectionResetError: Cannot write to closing transport
2025-01-10 07:48:11,701 - INFO - Shard ID None has successfully RESUMED session 1ce28411313d04074b67122edc37477b.
2025-01-10 08:19:21,645 - ERROR - Ignoring exception in on_message
Traceback (most recent call last):
  File "/home/container/.local/lib/python3.12/site-packages/discord/client.py", line 449, in _run_event
    await coro(*args, **kwargs)
  File "/home/container/cogs/afk_cog.py", line 109, in on_message
    time_diff = datetime.utcnow() - timestamp
                ~~~~~~~~~~~~~~~~~~^~~~~~~~~~~
TypeError: unsupported operand type(s) for -: 'datetime.datetime' and 'str'
2025-01-10 08:19:30,930 - ERROR - Ignoring exception in command None
discord.ext.commands.errors.CommandNotFound: Command "." is not found
2025-01-10 08:23:10,616 - ERROR - Ignoring exception in command None
discord.ext.commands.errors.CommandNotFound: Command "." is not found
2025-01-10 08:23:12,515 - ERROR - Ignoring exception in command None
discord.ext.commands.errors.CommandNotFound: Command ".." is not found
2025-01-10 08:23:13,861 - ERROR - Ignoring exception in command None
discord.ext.commands.errors.CommandNotFound: Command "..." is not found
2025-01-10 08:23:15,967 - ERROR - Ignoring exception in command None
discord.ext.commands.errors.CommandNotFound: Command "...." is not found
2025-01-10 08:55:22,315 - INFO - Shard ID None has successfully RESUMED session 1ce28411313d04074b67122edc37477b.
2025-01-10 09:31:55,757 - ERROR - Ignoring exception in command None
discord.ext.commands.errors.CommandNotFound: Command ".." is not found
2025-01-10 09:31:55,758 - ERROR - Ignoring exception in command None
discord.ext.commands.errors.CommandNotFound: Command ".." is not found
2025-01-10 09:40:16,543 - ERROR - Ignoring exception in command None
discord.ext.commands.errors.CommandNotFound: Command "play" is not found
2025-01-10 10:48:13,846 - WARNING - Can't keep up, shard ID None websocket is 41.9s behind.
2025-01-10 10:57:11,379 - WARNING - Can't keep up, shard ID None websocket is 42.4s behind.
2025-01-10 11:04:50,386 - WARNING - Can't keep up, shard ID None websocket is 43.2s behind.
2025-01-10 11:19:31,294 - ERROR - Attempting a reconnect in 0.44s
Traceback (most recent call last):
  File "/home/container/.local/lib/python3.12/site-packages/discord/client.py", line 667, in connect
    await self.ws.poll_event()
  File "/home/container/.local/lib/python3.12/site-packages/discord/gateway.py", line 625, in poll_event
    await self.received_message(msg.data)
  File "/home/container/.local/lib/python3.12/site-packages/discord/gateway.py", line 533, in received_message
    await self.send_as_json(beat)
  File "/home/container/.local/lib/python3.12/site-packages/discord/gateway.py", line 661, in send_as_json
    await self.send(utils._to_json(data))
  File "/home/container/.local/lib/python3.12/site-packages/discord/gateway.py", line 657, in send
    await self.socket.send_str(data)
  File "/home/container/.local/lib/python3.12/site-packages/aiohttp/client_ws.py", line 243, in send_str
    await self._writer.send_frame(
  File "/home/container/.local/lib/python3.12/site-packages/aiohttp/_websocket/writer.py", line 125, in send_frame
    raise ClientConnectionResetError("Cannot write to closing transport")
aiohttp.client_exceptions.ClientConnectionResetError: Cannot write to closing transport
2025-01-10 11:19:37,927 - INFO - Shard ID None has successfully RESUMED session 1ce28411313d04074b67122edc37477b.
2025-01-10 11:19:42,271 - ERROR - Ignoring exception in command None
discord.ext.commands.errors.CommandNotFound: Command "..." is not found
2025-01-10 11:19:42,283 - ERROR - Ignoring exception in command None
discord.ext.commands.errors.CommandNotFound: Command "..." is not found
2025-01-10 12:19:24,520 - ERROR - Ignoring exception in command None
discord.ext.commands.errors.CommandNotFound: Command "...cow.....ya....ab" is not found
2025-01-10 12:19:24,904 - ERROR - Ignoring exception in command None
discord.ext.commands.errors.CommandNotFound: Command "...cow.....ya....ab" is not found
2025-01-10 13:15:13,326 - ERROR - Ignoring exception in command None
discord.ext.commands.errors.CommandNotFound: Command ".." is not found
2025-01-10 13:15:13,327 - ERROR - Ignoring exception in command None
discord.ext.commands.errors.CommandNotFound: Command ".." is not found
2025-01-10 14:05:18,841 - ERROR - Attempting a reconnect in 0.37s
Traceback (most recent call last):
  File "/home/container/.local/lib/python3.12/site-packages/discord/client.py", line 667, in connect
    await self.ws.poll_event()
  File "/home/container/.local/lib/python3.12/site-packages/discord/gateway.py", line 625, in poll_event
    await self.received_message(msg.data)
  File "/home/container/.local/lib/python3.12/site-packages/discord/gateway.py", line 533, in received_message
    await self.send_as_json(beat)
  File "/home/container/.local/lib/python3.12/site-packages/discord/gateway.py", line 661, in send_as_json
    await self.send(utils._to_json(data))
  File "/home/container/.local/lib/python3.12/site-packages/discord/gateway.py", line 657, in send
    await self.socket.send_str(data)
  File "/home/container/.local/lib/python3.12/site-packages/aiohttp/client_ws.py", line 243, in send_str
    await self._writer.send_frame(
  File "/home/container/.local/lib/python3.12/site-packages/aiohttp/_websocket/writer.py", line 125, in send_frame
    raise ClientConnectionResetError("Cannot write to closing transport")
aiohttp.client_exceptions.ClientConnectionResetError: Cannot write to closing transport
2025-01-10 14:05:19,672 - WARNING - Shard ID None heartbeat blocked for more than 10 seconds.
Loop thread traceback (most recent call last):
  File "/home/container/main.py", line 86, in <module>
    bot.run(DISCORD_TOKEN)
  File "/home/container/.local/lib/python3.12/site-packages/discord/client.py", line 869, in run
    asyncio.run(runner())
  File "/usr/local/lib/python3.12/asyncio/runners.py", line 194, in run
    return runner.run(main)
  File "/usr/local/lib/python3.12/asyncio/runners.py", line 118, in run
    return self._loop.run_until_complete(task)
  File "/usr/local/lib/python3.12/asyncio/base_events.py", line 673, in run_until_complete
    self.run_forever()
  File "/usr/local/lib/python3.12/asyncio/base_events.py", line 640, in run_forever
    self._run_once()
  File "/usr/local/lib/python3.12/asyncio/base_events.py", line 1992, in _run_once
    handle._run()
  File "/usr/local/lib/python3.12/asyncio/events.py", line 88, in _run
    self._context.run(self._callback, *self._args)
  File "/home/container/.local/lib/python3.12/site-packages/discord/client.py", line 449, in _run_event
    await coro(*args, **kwargs)
  File "/home/container/cogs/sticky.py", line 128, in on_message
    last_message = await message.channel.fetch_message(last_message_id)
  File "/home/container/.local/lib/python3.12/site-packages/discord/abc.py", line 1684, in fetch_message
    data = await self._state.http.get_message(channel.id, id)
  File "/home/container/.local/lib/python3.12/site-packages/discord/http.py", line 638, in request
    async with self.__session.request(method, url, **kwargs) as response:
  File "/home/container/.local/lib/python3.12/site-packages/aiohttp/client.py", line 1425, in __aenter__
    self._resp: _RetType = await self._coro
  File "/home/container/.local/lib/python3.12/site-packages/aiohttp/client.py", line 658, in _request
    all_cookies = self._cookie_jar.filter_cookies(url)
  File "/home/container/.local/lib/python3.12/site-packages/aiohttp/cookiejar.py", line 349, in filter_cookies
    paths = itertools.accumulate(request_url.path.split("/"), _FORMAT_PATH)
  File "/home/container/.local/lib/python3.12/site-packages/yarl/_url.py", line 843, in path
    return PATH_UNQUOTER(self._path) if self._path else "/" if self._netloc else ""

2025-01-10 14:05:26,290 - INFO - Shard ID None has successfully RESUMED session 1ce28411313d04074b67122edc37477b.
2025-01-10 14:11:15,878 - ERROR - Attempting a reconnect in 1.89s
Traceback (most recent call last):
  File "/home/container/.local/lib/python3.12/site-packages/discord/client.py", line 667, in connect
    await self.ws.poll_event()
  File "/home/container/.local/lib/python3.12/site-packages/discord/gateway.py", line 648, in poll_event
    raise ConnectionClosed(self.socket, shard_id=self.shard_id, code=code) from None
discord.errors.ConnectionClosed: Shard ID None WebSocket closed with 1000
2025-01-10 14:11:36,878 - INFO - Shard ID None has successfully RESUMED session 1ce28411313d04074b67122edc37477b.
2025-01-10 14:13:55,012 - ERROR - Attempting a reconnect in 2.50s
Traceback (most recent call last):
  File "/home/container/.local/lib/python3.12/site-packages/aiohttp/connector.py", line 1351, in _create_direct_connection
    hosts = await self._resolve_host(host, port, traces=traces)
            ^^^^^^^^^^^^^^^^^^^^^^^^^^^^^^^^^^^^^^^^^^^^^^^^^^^
  File "/home/container/.local/lib/python3.12/site-packages/aiohttp/connector.py", line 995, in _resolve_host
    return await asyncio.shield(resolved_host_task)
           ^^^^^^^^^^^^^^^^^^^^^^^^^^^^^^^^^^^^^^^^
  File "/home/container/.local/lib/python3.12/site-packages/aiohttp/connector.py", line 1026, in _resolve_host_with_throttle
    addrs = await self._resolver.resolve(host, port, family=self._family)
            ^^^^^^^^^^^^^^^^^^^^^^^^^^^^^^^^^^^^^^^^^^^^^^^^^^^^^^^^^^^^^
  File "/home/container/.local/lib/python3.12/site-packages/aiohttp/resolver.py", line 36, in resolve
    infos = await self._loop.getaddrinfo(
            ^^^^^^^^^^^^^^^^^^^^^^^^^^^^^
  File "/usr/local/lib/python3.12/asyncio/base_events.py", line 900, in getaddrinfo
    return await self.run_in_executor(
           ^^^^^^^^^^^^^^^^^^^^^^^^^^^
  File "/usr/local/lib/python3.12/concurrent/futures/thread.py", line 59, in run
    result = self.fn(*self.args, **self.kwargs)
             ^^^^^^^^^^^^^^^^^^^^^^^^^^^^^^^^^^
  File "/usr/local/lib/python3.12/socket.py", line 976, in getaddrinfo
    for res in _socket.getaddrinfo(host, port, family, type, proto, flags):
               ^^^^^^^^^^^^^^^^^^^^^^^^^^^^^^^^^^^^^^^^^^^^^^^^^^^^^^^^^^^
socket.gaierror: [Errno -3] Temporary failure in name resolution

The above exception was the direct cause of the following exception:

Traceback (most recent call last):
  File "/home/container/.local/lib/python3.12/site-packages/discord/client.py", line 664, in connect
    self.ws = await asyncio.wait_for(coro, timeout=60.0)
              ^^^^^^^^^^^^^^^^^^^^^^^^^^^^^^^^^^^^^^^^^^
  File "/usr/local/lib/python3.12/asyncio/tasks.py", line 520, in wait_for
    return await fut
           ^^^^^^^^^
  File "/home/container/.local/lib/python3.12/site-packages/discord/gateway.py", line 374, in from_client
    socket = await client.http.ws_connect(str(url))
             ^^^^^^^^^^^^^^^^^^^^^^^^^^^^^^^^^^^^^^
  File "/home/container/.local/lib/python3.12/site-packages/discord/http.py", line 550, in ws_connect
    return await self.__session.ws_connect(url, **kwargs)
           ^^^^^^^^^^^^^^^^^^^^^^^^^^^^^^^^^^^^^^^^^^^^^^
  File "/home/container/.local/lib/python3.12/site-packages/aiohttp/client.py", line 1004, in _ws_connect
    resp = await self.request(
           ^^^^^^^^^^^^^^^^^^^
  File "/home/container/.local/lib/python3.12/site-packages/aiohttp/client.py", line 703, in _request
    conn = await self._connector.connect(
           ^^^^^^^^^^^^^^^^^^^^^^^^^^^^^^
  File "/home/container/.local/lib/python3.12/site-packages/aiohttp/connector.py", line 548, in connect
    proto = await self._create_connection(req, traces, timeout)
            ^^^^^^^^^^^^^^^^^^^^^^^^^^^^^^^^^^^^^^^^^^^^^^^^^^^
  File "/home/container/.local/lib/python3.12/site-packages/aiohttp/connector.py", line 1056, in _create_connection
    _, proto = await self._create_direct_connection(req, traces, timeout)
               ^^^^^^^^^^^^^^^^^^^^^^^^^^^^^^^^^^^^^^^^^^^^^^^^^^^^^^^^^^
  File "/home/container/.local/lib/python3.12/site-packages/aiohttp/connector.py", line 1357, in _create_direct_connection
    raise ClientConnectorDNSError(req.connection_key, exc) from exc
aiohttp.client_exceptions.ClientConnectorDNSError: Cannot connect to host gateway-us-east1-b.discord.gg:443 ssl:default [Temporary failure in name resolution]
2025-01-10 14:14:01,996 - INFO - Shard ID None has successfully RESUMED session 1ce28411313d04074b67122edc37477b.
2025-01-10 14:17:18,591 - ERROR - Ignoring exception in command None
discord.ext.commands.errors.CommandNotFound: Command "av" is not found
2025-01-10 14:34:17,503 - ERROR - Ignoring exception in command None
discord.ext.commands.errors.CommandNotFound: Command "voice" is not found
2025-01-10 15:37:28,692 - INFO - Shard ID None has successfully RESUMED session c65d672fa5405439782700919b763ce5.
2025-01-10 16:08:17,510 - INFO - Shard ID None has successfully RESUMED session c65d672fa5405439782700919b763ce5.
2025-01-10 16:23:51,381 - ERROR - Ignoring exception in command None
discord.ext.commands.errors.CommandNotFound: Command "....." is not found
2025-01-10 16:23:51,383 - ERROR - Ignoring exception in command None
discord.ext.commands.errors.CommandNotFound: Command "....." is not found
2025-01-10 16:47:53,054 - ERROR - Ignoring exception in command None
discord.ext.commands.errors.CommandNotFound: Command "...." is not found
2025-01-10 17:08:41,297 - ERROR - Ignoring exception in command None
discord.ext.commands.errors.CommandNotFound: Command ".." is not found
2025-01-10 17:14:46,606 - INFO - Shard ID None has successfully RESUMED session c65d672fa5405439782700919b763ce5.
2025-01-10 17:18:10,492 - ERROR - Ignoring exception in command None
discord.ext.commands.errors.CommandNotFound: Command "..." is not found
2025-01-10 17:18:20,409 - INFO - Shard ID None has successfully RESUMED session c65d672fa5405439782700919b763ce5.
2025-01-10 17:19:06,779 - ERROR - Ignoring exception in command None
discord.ext.commands.errors.CommandNotFound: Command ".." is not found
2025-01-10 17:26:08,699 - INFO - Shard ID None has successfully RESUMED session c65d672fa5405439782700919b763ce5.
2025-01-10 17:26:22,056 - ERROR - Ignoring exception in command None
discord.ext.commands.errors.CommandNotFound: Command "." is not found
2025-01-10 17:47:20,240 - ERROR - Ignoring exception in command None
discord.ext.commands.errors.CommandNotFound: Command ".." is not found
2025-01-10 18:28:03,018 - INFO - Shard ID None has successfully RESUMED session c65d672fa5405439782700919b763ce5.
2025-01-10 18:37:43,315 - WARNING - Can't keep up, shard ID None websocket is 42.7s behind.
2025-01-10 19:24:42,523 - ERROR - Ignoring exception in command None
discord.ext.commands.errors.CommandNotFound: Command "av" is not found
2025-01-10 19:24:42,529 - ERROR - Ignoring exception in command None
discord.ext.commands.errors.CommandNotFound: Command "av" is not found
2025-01-10 19:59:09,614 - ERROR - Ignoring exception in command None
discord.ext.commands.errors.CommandNotFound: Command "...." is not found
2025-01-10 19:59:09,615 - ERROR - Ignoring exception in command None
discord.ext.commands.errors.CommandNotFound: Command "...." is not found
2025-01-10 20:01:29,854 - INFO - Shard ID None has successfully RESUMED session c65d672fa5405439782700919b763ce5.
2025-01-10 20:15:57,863 - ERROR - Ignoring exception in command None
discord.ext.commands.errors.CommandNotFound: Command "." is not found
2025-01-10 20:29:40,746 - ERROR - Ignoring exception in command None
discord.ext.commands.errors.CommandNotFound: Command "." is not found
2025-01-10 20:29:41,371 - ERROR - Ignoring exception in command None
discord.ext.commands.errors.CommandNotFound: Command "." is not found
2025-01-10 20:33:33,257 - ERROR - Ignoring exception in command None
discord.ext.commands.errors.CommandNotFound: Command ".." is not found
2025-01-10 20:33:44,176 - ERROR - Ignoring exception in command None
discord.ext.commands.errors.CommandNotFound: Command "..." is not found
2025-01-10 20:33:44,222 - ERROR - Ignoring exception in command None
discord.ext.commands.errors.CommandNotFound: Command "..." is not found
2025-01-10 20:37:19,574 - WARNING - Can't keep up, shard ID None websocket is 42.3s behind.
2025-01-10 20:40:52,683 - WARNING - Can't keep up, shard ID None websocket is 41.9s behind.
2025-01-10 20:47:26,055 - ERROR - Ignoring exception in command None
discord.ext.commands.errors.CommandNotFound: Command "boob" is not found
2025-01-10 20:47:26,061 - ERROR - Ignoring exception in command None
discord.ext.commands.errors.CommandNotFound: Command "boob" is not found
2025-01-10 20:50:28,499 - ERROR - Ignoring exception in command None
discord.ext.commands.errors.CommandNotFound: Command "..." is not found
2025-01-10 21:19:28,061 - WARNING - Can't keep up, shard ID None websocket is 41.7s behind.
2025-01-10 21:42:02,679 - ERROR - Ignoring exception in command None
discord.ext.commands.errors.CommandNotFound: Command "_." is not found
2025-01-10 21:42:04,095 - ERROR - Ignoring exception in command None
discord.ext.commands.errors.CommandNotFound: Command "_." is not found
2025-01-10 21:48:28,567 - ERROR - Ignoring exception in command None
discord.ext.commands.errors.CommandNotFound: Command "_." is not found
2025-01-10 21:48:28,576 - ERROR - Ignoring exception in command None
discord.ext.commands.errors.CommandNotFound: Command "_." is not found
2025-01-10 21:51:39,334 - ERROR - Ignoring exception in command None
discord.ext.commands.errors.CommandNotFound: Command "..." is not found
2025-01-10 21:51:39,349 - ERROR - Ignoring exception in command None
discord.ext.commands.errors.CommandNotFound: Command "..." is not found
2025-01-10 21:59:13,262 - ERROR - Ignoring exception in command None
discord.ext.commands.errors.CommandNotFound: Command "_." is not found
2025-01-10 21:59:13,325 - ERROR - Ignoring exception in command None
discord.ext.commands.errors.CommandNotFound: Command "_." is not found
2025-01-10 22:09:05,640 - ERROR - Ignoring exception in command None
discord.ext.commands.errors.CommandNotFound: Command ".." is not found
2025-01-10 22:09:06,563 - ERROR - Ignoring exception in command None
discord.ext.commands.errors.CommandNotFound: Command ".." is not found
2025-01-10 22:09:59,042 - ERROR - Ignoring exception in command None
discord.ext.commands.errors.CommandNotFound: Command ".." is not found
2025-01-10 22:09:59,098 - ERROR - Ignoring exception in command None
discord.ext.commands.errors.CommandNotFound: Command ".." is not found
2025-01-10 22:43:43,158 - WARNING - Can't keep up, shard ID None websocket is 46.6s behind.
2025-01-10 23:19:36,280 - INFO - Shard ID None has successfully RESUMED session c65d672fa5405439782700919b763ce5.
2025-01-10 23:30:30,635 - ERROR - Ignoring exception in command None
discord.ext.commands.errors.CommandNotFound: Command "." is not found
2025-01-10 23:30:31,047 - ERROR - Ignoring exception in command None
discord.ext.commands.errors.CommandNotFound: Command "." is not found
2025-01-10 23:30:50,873 - ERROR - Ignoring exception in command None
discord.ext.commands.errors.CommandNotFound: Command "." is not found
2025-01-10 23:34:48,786 - WARNING - Can't keep up, shard ID None websocket is 42.6s behind.
2025-01-10 23:45:18,948 - ERROR - Ignoring exception in on_message
Traceback (most recent call last):
  File "/home/container/.local/lib/python3.12/site-packages/discord/client.py", line 449, in _run_event
    await coro(*args, **kwargs)
  File "/home/container/cogs/thread.py", line 55, in on_message
    thread = await message.create_thread(name=thread_name, auto_archive_duration=1440)
             ^^^^^^^^^^^^^^^^^^^^^^^^^^^^^^^^^^^^^^^^^^^^^^^^^^^^^^^^^^^^^^^^^^^^^^^^^
  File "/home/container/.local/lib/python3.12/site-packages/discord/message.py", line 1407, in create_thread
    data = await self._state.http.start_thread_with_message(
           ^^^^^^^^^^^^^^^^^^^^^^^^^^^^^^^^^^^^^^^^^^^^^^^^^
  File "/home/container/.local/lib/python3.12/site-packages/discord/http.py", line 758, in request
    raise HTTPException(response, data)
discord.errors.HTTPException: 400 Bad Request (error code: 10008): Unknown Message
2025-01-11 00:13:29,215 - ERROR - Attempting a reconnect in 0.18s
Traceback (most recent call last):
  File "/home/container/.local/lib/python3.12/site-packages/discord/client.py", line 667, in connect
    await self.ws.poll_event()
  File "/home/container/.local/lib/python3.12/site-packages/discord/gateway.py", line 625, in poll_event
    await self.received_message(msg.data)
  File "/home/container/.local/lib/python3.12/site-packages/discord/gateway.py", line 533, in received_message
    await self.send_as_json(beat)
  File "/home/container/.local/lib/python3.12/site-packages/discord/gateway.py", line 661, in send_as_json
    await self.send(utils._to_json(data))
  File "/home/container/.local/lib/python3.12/site-packages/discord/gateway.py", line 657, in send
    await self.socket.send_str(data)
  File "/home/container/.local/lib/python3.12/site-packages/aiohttp/client_ws.py", line 243, in send_str
    await self._writer.send_frame(
  File "/home/container/.local/lib/python3.12/site-packages/aiohttp/_websocket/writer.py", line 125, in send_frame
    raise ClientConnectionResetError("Cannot write to closing transport")
aiohttp.client_exceptions.ClientConnectionResetError: Cannot write to closing transport
2025-01-11 00:13:43,429 - INFO - Shard ID None has successfully RESUMED session c65d672fa5405439782700919b763ce5.
2025-01-11 01:27:18,390 - INFO - Shard ID None has successfully RESUMED session c65d672fa5405439782700919b763ce5.
2025-01-11 01:38:05,925 - ERROR - Ignoring exception in command purge
Traceback (most recent call last):
  File "/home/container/.local/lib/python3.12/site-packages/discord/ext/commands/bot.py", line 1366, in invoke
    await ctx.command.invoke(ctx)
  File "/home/container/.local/lib/python3.12/site-packages/discord/ext/commands/core.py", line 1021, in invoke
    await self.prepare(ctx)
  File "/home/container/.local/lib/python3.12/site-packages/discord/ext/commands/core.py", line 925, in prepare
    if not await self.can_run(ctx):
           ^^^^^^^^^^^^^^^^^^^^^^^
  File "/home/container/.local/lib/python3.12/site-packages/discord/ext/commands/core.py", line 1288, in can_run
    return await discord.utils.async_all(predicate(ctx) for predicate in predicates)
           ^^^^^^^^^^^^^^^^^^^^^^^^^^^^^^^^^^^^^^^^^^^^^^^^^^^^^^^^^^^^^^^^^^^^^^^^^
  File "/home/container/.local/lib/python3.12/site-packages/discord/utils.py", line 704, in async_all
    for elem in gen:
                ^^^
  File "/home/container/.local/lib/python3.12/site-packages/discord/ext/commands/core.py", line 1288, in <genexpr>
    return await discord.utils.async_all(predicate(ctx) for predicate in predicates)
                                         ^^^^^^^^^^^^^^
  File "/home/container/.local/lib/python3.12/site-packages/discord/ext/commands/core.py", line 2210, in predicate
    raise MissingPermissions(missing)
discord.ext.commands.errors.MissingPermissions: You are missing Manage Messages permission(s) to run this command.
2025-01-11 01:39:52,322 - ERROR - Ignoring exception in command purge
Traceback (most recent call last):
  File "/home/container/.local/lib/python3.12/site-packages/discord/ext/commands/bot.py", line 1366, in invoke
    await ctx.command.invoke(ctx)
  File "/home/container/.local/lib/python3.12/site-packages/discord/ext/commands/core.py", line 1021, in invoke
    await self.prepare(ctx)
  File "/home/container/.local/lib/python3.12/site-packages/discord/ext/commands/core.py", line 925, in prepare
    if not await self.can_run(ctx):
           ^^^^^^^^^^^^^^^^^^^^^^^
  File "/home/container/.local/lib/python3.12/site-packages/discord/ext/commands/core.py", line 1288, in can_run
    return await discord.utils.async_all(predicate(ctx) for predicate in predicates)
           ^^^^^^^^^^^^^^^^^^^^^^^^^^^^^^^^^^^^^^^^^^^^^^^^^^^^^^^^^^^^^^^^^^^^^^^^^
  File "/home/container/.local/lib/python3.12/site-packages/discord/utils.py", line 704, in async_all
    for elem in gen:
                ^^^
  File "/home/container/.local/lib/python3.12/site-packages/discord/ext/commands/core.py", line 1288, in <genexpr>
    return await discord.utils.async_all(predicate(ctx) for predicate in predicates)
                                         ^^^^^^^^^^^^^^
  File "/home/container/.local/lib/python3.12/site-packages/discord/ext/commands/core.py", line 2210, in predicate
    raise MissingPermissions(missing)
discord.ext.commands.errors.MissingPermissions: You are missing Manage Messages permission(s) to run this command.
2025-01-11 01:44:03,946 - ERROR - Ignoring exception in command None
discord.ext.commands.errors.CommandNotFound: Command "." is not found
2025-01-11 01:44:09,590 - ERROR - Ignoring exception in command None
discord.ext.commands.errors.CommandNotFound: Command ".." is not found
2025-01-11 01:45:22,909 - INFO - Shard ID None has successfully RESUMED session c65d672fa5405439782700919b763ce5.
2025-01-11 02:52:58,884 - INFO - Shard ID None has successfully RESUMED session c65d672fa5405439782700919b763ce5.
2025-01-11 04:23:36,111 - ERROR - Attempting a reconnect in 1.81s
Traceback (most recent call last):
  File "/home/container/.local/lib/python3.12/site-packages/discord/client.py", line 667, in connect
    await self.ws.poll_event()
  File "/home/container/.local/lib/python3.12/site-packages/discord/gateway.py", line 625, in poll_event
    await self.received_message(msg.data)
  File "/home/container/.local/lib/python3.12/site-packages/discord/gateway.py", line 533, in received_message
    await self.send_as_json(beat)
  File "/home/container/.local/lib/python3.12/site-packages/discord/gateway.py", line 661, in send_as_json
    await self.send(utils._to_json(data))
  File "/home/container/.local/lib/python3.12/site-packages/discord/gateway.py", line 657, in send
    await self.socket.send_str(data)
  File "/home/container/.local/lib/python3.12/site-packages/aiohttp/client_ws.py", line 243, in send_str
    await self._writer.send_frame(
  File "/home/container/.local/lib/python3.12/site-packages/aiohttp/_websocket/writer.py", line 125, in send_frame
    raise ClientConnectionResetError("Cannot write to closing transport")
aiohttp.client_exceptions.ClientConnectionResetError: Cannot write to closing transport
2025-01-11 04:23:42,037 - WARNING - Shard ID None heartbeat blocked for more than 10 seconds.
Loop thread traceback (most recent call last):
  File "/home/container/main.py", line 86, in <module>
    bot.run(DISCORD_TOKEN)
  File "/home/container/.local/lib/python3.12/site-packages/discord/client.py", line 869, in run
    asyncio.run(runner())
  File "/usr/local/lib/python3.12/asyncio/runners.py", line 194, in run
    return runner.run(main)
  File "/usr/local/lib/python3.12/asyncio/runners.py", line 118, in run
    return self._loop.run_until_complete(task)
  File "/usr/local/lib/python3.12/asyncio/base_events.py", line 673, in run_until_complete
    self.run_forever()
  File "/usr/local/lib/python3.12/asyncio/base_events.py", line 640, in run_forever
    self._run_once()
  File "/usr/local/lib/python3.12/asyncio/base_events.py", line 1992, in _run_once
    handle._run()
  File "/usr/local/lib/python3.12/asyncio/events.py", line 88, in _run
    self._context.run(self._callback, *self._args)
  File "/home/container/.local/lib/python3.12/site-packages/discord/gateway.py", line 669, in send_heartbeat
    await self.socket.send_str(utils._to_json(data))
  File "/home/container/.local/lib/python3.12/site-packages/aiohttp/client_ws.py", line 243, in send_str
    await self._writer.send_frame(
  File "/home/container/.local/lib/python3.12/site-packages/aiohttp/_websocket/writer.py", line 138, in send_frame
    self.transport.write(header + mask + message)
  File "/usr/local/lib/python3.12/asyncio/sslproto.py", line 222, in write
    self._ssl_protocol._write_appdata((data,))
  File "/usr/local/lib/python3.12/asyncio/sslproto.py", line 697, in _write_appdata
    self._do_write()
  File "/usr/local/lib/python3.12/asyncio/sslproto.py", line 706, in _do_write
    count = self._sslobj.write(data)
  File "/usr/local/lib/python3.12/ssl.py", line 867, in write
    return self._sslobj.write(data)

2025-01-11 04:23:50,695 - INFO - Shard ID None has successfully RESUMED session c65d672fa5405439782700919b763ce5.
2025-01-11 04:36:56,983 - WARNING - Shard ID None heartbeat blocked for more than 10 seconds.
Loop thread traceback (most recent call last):
  File "/home/container/main.py", line 86, in <module>
    bot.run(DISCORD_TOKEN)
  File "/home/container/.local/lib/python3.12/site-packages/discord/client.py", line 869, in run
    asyncio.run(runner())
  File "/usr/local/lib/python3.12/asyncio/runners.py", line 194, in run
    return runner.run(main)
  File "/usr/local/lib/python3.12/asyncio/runners.py", line 118, in run
    return self._loop.run_until_complete(task)
  File "/usr/local/lib/python3.12/asyncio/base_events.py", line 673, in run_until_complete
    self.run_forever()
  File "/usr/local/lib/python3.12/asyncio/base_events.py", line 640, in run_forever
    self._run_once()
  File "/usr/local/lib/python3.12/asyncio/base_events.py", line 1992, in _run_once
    handle._run()
  File "/usr/local/lib/python3.12/asyncio/events.py", line 88, in _run
    self._context.run(self._callback, *self._args)
  File "/home/container/.local/lib/python3.12/site-packages/discord/ext/tasks/__init__.py", line 241, in _loop
    await self.coro(*args, **kwargs)
  File "/home/container/cogs/sticky.py", line 176, in sticky_task
    self.save_sticky_data()
  File "/home/container/cogs/sticky.py", line 40, in save_sticky_data
    with open('sticky_data.json', 'w') as file:

2025-01-11 04:36:57,877 - WARNING - Can't keep up, shard ID None websocket is 55.7s behind.
2025-01-11 04:40:20,191 - ERROR - Attempting a reconnect in 1.69s
Traceback (most recent call last):
  File "/home/container/.local/lib/python3.12/site-packages/discord/client.py", line 667, in connect
    await self.ws.poll_event()
  File "/home/container/.local/lib/python3.12/site-packages/discord/gateway.py", line 625, in poll_event
    await self.received_message(msg.data)
  File "/home/container/.local/lib/python3.12/site-packages/discord/gateway.py", line 533, in received_message
    await self.send_as_json(beat)
  File "/home/container/.local/lib/python3.12/site-packages/discord/gateway.py", line 661, in send_as_json
    await self.send(utils._to_json(data))
  File "/home/container/.local/lib/python3.12/site-packages/discord/gateway.py", line 657, in send
    await self.socket.send_str(data)
  File "/home/container/.local/lib/python3.12/site-packages/aiohttp/client_ws.py", line 243, in send_str
    await self._writer.send_frame(
  File "/home/container/.local/lib/python3.12/site-packages/aiohttp/_websocket/writer.py", line 125, in send_frame
    raise ClientConnectionResetError("Cannot write to closing transport")
aiohttp.client_exceptions.ClientConnectionResetError: Cannot write to closing transport
2025-01-11 04:40:28,041 - INFO - Shard ID None has successfully RESUMED session c65d672fa5405439782700919b763ce5.
2025-01-11 04:49:34,531 - WARNING - Shard ID None has stopped responding to the gateway. Closing and restarting.
2025-01-11 04:49:34,871 - ERROR - Attempting a reconnect in 0.21s
Traceback (most recent call last):
  File "/home/container/.local/lib/python3.12/site-packages/discord/client.py", line 667, in connect
    await self.ws.poll_event()
  File "/home/container/.local/lib/python3.12/site-packages/discord/gateway.py", line 625, in poll_event
    await self.received_message(msg.data)
  File "/home/container/.local/lib/python3.12/site-packages/discord/gateway.py", line 533, in received_message
    await self.send_as_json(beat)
  File "/home/container/.local/lib/python3.12/site-packages/discord/gateway.py", line 661, in send_as_json
    await self.send(utils._to_json(data))
  File "/home/container/.local/lib/python3.12/site-packages/discord/gateway.py", line 657, in send
    await self.socket.send_str(data)
  File "/home/container/.local/lib/python3.12/site-packages/aiohttp/client_ws.py", line 243, in send_str
    await self._writer.send_frame(
  File "/home/container/.local/lib/python3.12/site-packages/aiohttp/_websocket/writer.py", line 125, in send_frame
    raise ClientConnectionResetError("Cannot write to closing transport")
aiohttp.client_exceptions.ClientConnectionResetError: Cannot write to closing transport
2025-01-11 04:49:39,677 - INFO - Shard ID None session has been invalidated.
2025-01-11 04:49:45,614 - INFO - Shard ID None has connected to Gateway (Session ID: 437e991d6386f6c4706cec2ff68dac0d).
2025-01-11 04:49:59,532 - ERROR - Ignoring exception in cog unload for Cog <class 'cogs.sticky.StickyBot'> ('StickyBot')
Traceback (most recent call last):
  File "/home/container/.local/lib/python3.12/site-packages/discord/ext/commands/cog.py", line 776, in _eject
    await maybe_coroutine(self.cog_unload)
  File "/home/container/.local/lib/python3.12/site-packages/discord/utils.py", line 694, in maybe_coroutine
    return await value
           ^^^^^^^^^^^
  File "/home/container/cogs/sticky.py", line 191, in cog_unload
    await self.sticky_task
TypeError: object Loop can't be used in 'await' expression
2025-01-11 05:09:08,443 - INFO - Shard ID None has successfully RESUMED session 437e991d6386f6c4706cec2ff68dac0d.
2025-01-11 05:17:47,674 - WARNING - Shard ID None has stopped responding to the gateway. Closing and restarting.
2025-01-11 05:17:50,049 - ERROR - Attempting a reconnect in 5.71s
Traceback (most recent call last):
  File "/home/container/.local/lib/python3.12/site-packages/discord/client.py", line 667, in connect
    await self.ws.poll_event()
  File "/home/container/.local/lib/python3.12/site-packages/discord/gateway.py", line 625, in poll_event
    await self.received_message(msg.data)
  File "/home/container/.local/lib/python3.12/site-packages/discord/gateway.py", line 533, in received_message
    await self.send_as_json(beat)
  File "/home/container/.local/lib/python3.12/site-packages/discord/gateway.py", line 661, in send_as_json
    await self.send(utils._to_json(data))
  File "/home/container/.local/lib/python3.12/site-packages/discord/gateway.py", line 657, in send
    await self.socket.send_str(data)
  File "/home/container/.local/lib/python3.12/site-packages/aiohttp/client_ws.py", line 243, in send_str
    await self._writer.send_frame(
  File "/home/container/.local/lib/python3.12/site-packages/aiohttp/_websocket/writer.py", line 125, in send_frame
    raise ClientConnectionResetError("Cannot write to closing transport")
aiohttp.client_exceptions.ClientConnectionResetError: Cannot write to closing transport
2025-01-11 05:18:33,293 - INFO - Shard ID None has successfully RESUMED session 437e991d6386f6c4706cec2ff68dac0d.
2025-01-11 05:22:17,983 - ERROR - Ignoring exception in command None
discord.ext.commands.errors.CommandNotFound: Command ".." is not found
2025-01-11 05:22:18,265 - ERROR - Ignoring exception in command None
discord.ext.commands.errors.CommandNotFound: Command ".." is not found
2025-01-11 05:26:19,494 - ERROR - Ignoring exception in command None
discord.ext.commands.errors.CommandNotFound: Command ".." is not found
2025-01-11 05:26:19,783 - ERROR - Ignoring exception in command None
discord.ext.commands.errors.CommandNotFound: Command ".." is not found
2025-01-11 05:27:11,312 - WARNING - Can't keep up, shard ID None websocket is 54.3s behind.
2025-01-11 05:27:18,272 - WARNING - Can't keep up, shard ID None websocket is 61.2s behind.
2025-01-11 05:37:49,170 - WARNING - Shard ID None has stopped responding to the gateway. Closing and restarting.
2025-01-11 05:37:50,933 - ERROR - Attempting a reconnect in 15.14s
Traceback (most recent call last):
  File "/home/container/.local/lib/python3.12/site-packages/discord/client.py", line 667, in connect
    await self.ws.poll_event()
  File "/home/container/.local/lib/python3.12/site-packages/discord/gateway.py", line 625, in poll_event
    await self.received_message(msg.data)
  File "/home/container/.local/lib/python3.12/site-packages/discord/gateway.py", line 533, in received_message
    await self.send_as_json(beat)
  File "/home/container/.local/lib/python3.12/site-packages/discord/gateway.py", line 661, in send_as_json
    await self.send(utils._to_json(data))
  File "/home/container/.local/lib/python3.12/site-packages/discord/gateway.py", line 657, in send
    await self.socket.send_str(data)
  File "/home/container/.local/lib/python3.12/site-packages/aiohttp/client_ws.py", line 243, in send_str
    await self._writer.send_frame(
  File "/home/container/.local/lib/python3.12/site-packages/aiohttp/_websocket/writer.py", line 125, in send_frame
    raise ClientConnectionResetError("Cannot write to closing transport")
aiohttp.client_exceptions.ClientConnectionResetError: Cannot write to closing transport
2025-01-11 05:38:07,393 - INFO - Shard ID None session has been invalidated.
2025-01-11 05:38:12,861 - INFO - Shard ID None has connected to Gateway (Session ID: 8c3fd00e15ff4035ad472de1f6aba1cc).
2025-01-11 05:38:15,918 - ERROR - Ignoring exception in cog unload for Cog <class 'cogs.sticky.StickyBot'> ('StickyBot')
Traceback (most recent call last):
  File "/home/container/.local/lib/python3.12/site-packages/discord/ext/commands/cog.py", line 776, in _eject
    await maybe_coroutine(self.cog_unload)
  File "/home/container/.local/lib/python3.12/site-packages/discord/utils.py", line 694, in maybe_coroutine
    return await value
           ^^^^^^^^^^^
  File "/home/container/cogs/sticky.py", line 191, in cog_unload
    await self.sticky_task
TypeError: object Loop can't be used in 'await' expression
2025-01-11 05:47:39,225 - WARNING - Shard ID None has stopped responding to the gateway. Closing and restarting.
2025-01-11 05:47:56,130 - INFO - Shard ID None has successfully RESUMED session 8c3fd00e15ff4035ad472de1f6aba1cc.
2025-01-11 06:09:39,664 - WARNING - Can't keep up, shard ID None websocket is 50.5s behind.
2025-01-11 06:09:55,332 - WARNING - Shard ID None heartbeat blocked for more than 10 seconds.
Loop thread traceback (most recent call last):
  File "/home/container/main.py", line 86, in <module>
    bot.run(DISCORD_TOKEN)
  File "/home/container/.local/lib/python3.12/site-packages/discord/client.py", line 869, in run
    asyncio.run(runner())
  File "/usr/local/lib/python3.12/asyncio/runners.py", line 194, in run
    return runner.run(main)
  File "/usr/local/lib/python3.12/asyncio/runners.py", line 118, in run
    return self._loop.run_until_complete(task)
  File "/usr/local/lib/python3.12/asyncio/base_events.py", line 673, in run_until_complete
    self.run_forever()
  File "/usr/local/lib/python3.12/asyncio/base_events.py", line 640, in run_forever
    self._run_once()
  File "/usr/local/lib/python3.12/asyncio/base_events.py", line 1992, in _run_once
    handle._run()
  File "/usr/local/lib/python3.12/asyncio/events.py", line 88, in _run
    self._context.run(self._callback, *self._args)
  File "/usr/local/lib/python3.12/asyncio/selector_events.py", line 970, in _read_ready
    self._read_ready_cb()
  File "/usr/local/lib/python3.12/asyncio/selector_events.py", line 1002, in _read_ready__get_buffer
    self._protocol.buffer_updated(nbytes)
  File "/usr/local/lib/python3.12/asyncio/sslproto.py", line 445, in buffer_updated
    self._do_read()
  File "/usr/local/lib/python3.12/asyncio/sslproto.py", line 740, in _do_read
    self._do_read__copied()
  File "/usr/local/lib/python3.12/asyncio/sslproto.py", line 785, in _do_read__copied
    chunk = self._sslobj.read(self.max_size)
  File "/usr/local/lib/python3.12/ssl.py", line 858, in read
    v = self._sslobj.read(len)

2025-01-11 06:10:07,336 - ERROR - Attempting a reconnect in 33.22s
Traceback (most recent call last):
  File "/home/container/.local/lib/python3.12/site-packages/discord/client.py", line 667, in connect
    await self.ws.poll_event()
  File "/home/container/.local/lib/python3.12/site-packages/discord/gateway.py", line 625, in poll_event
    await self.received_message(msg.data)
  File "/home/container/.local/lib/python3.12/site-packages/discord/gateway.py", line 533, in received_message
    await self.send_as_json(beat)
  File "/home/container/.local/lib/python3.12/site-packages/discord/gateway.py", line 661, in send_as_json
    await self.send(utils._to_json(data))
  File "/home/container/.local/lib/python3.12/site-packages/discord/gateway.py", line 657, in send
    await self.socket.send_str(data)
  File "/home/container/.local/lib/python3.12/site-packages/aiohttp/client_ws.py", line 243, in send_str
    await self._writer.send_frame(
  File "/home/container/.local/lib/python3.12/site-packages/aiohttp/_websocket/writer.py", line 125, in send_frame
    raise ClientConnectionResetError("Cannot write to closing transport")
aiohttp.client_exceptions.ClientConnectionResetError: Cannot write to closing transport
2025-01-11 06:10:45,350 - INFO - Shard ID None has successfully RESUMED session 8c3fd00e15ff4035ad472de1f6aba1cc.
2025-01-11 06:21:33,367 - WARNING - Shard ID None heartbeat blocked for more than 10 seconds.
Loop thread traceback (most recent call last):
  File "/home/container/main.py", line 86, in <module>
    bot.run(DISCORD_TOKEN)
  File "/home/container/.local/lib/python3.12/site-packages/discord/client.py", line 869, in run
    asyncio.run(runner())
  File "/usr/local/lib/python3.12/asyncio/runners.py", line 194, in run
    return runner.run(main)
  File "/usr/local/lib/python3.12/asyncio/runners.py", line 118, in run
    return self._loop.run_until_complete(task)
  File "/usr/local/lib/python3.12/asyncio/base_events.py", line 673, in run_until_complete
    self.run_forever()
  File "/usr/local/lib/python3.12/asyncio/base_events.py", line 640, in run_forever
    self._run_once()
  File "/usr/local/lib/python3.12/asyncio/base_events.py", line 1992, in _run_once
    handle._run()
  File "/usr/local/lib/python3.12/asyncio/events.py", line 88, in _run
    self._context.run(self._callback, *self._args)
  File "/home/container/.local/lib/python3.12/site-packages/discord/ext/tasks/__init__.py", line 241, in _loop
    await self.coro(*args, **kwargs)
  File "/home/container/cogs/status_changer.py", line 32, in status_cycle
    await self.change_status(line.strip())  # Cycle through each status
  File "/home/container/cogs/status_changer.py", line 43, in change_status
    logging.info(f"Status changed to: {message}")
  File "/usr/local/lib/python3.12/logging/__init__.py", line 2216, in info
    root.info(msg, *args, **kwargs)
  File "/usr/local/lib/python3.12/logging/__init__.py", line 1539, in info
    self._log(INFO, msg, args, **kwargs)
  File "/usr/local/lib/python3.12/logging/__init__.py", line 1684, in _log
    self.handle(record)
  File "/usr/local/lib/python3.12/logging/__init__.py", line 1700, in handle
    self.callHandlers(record)
  File "/usr/local/lib/python3.12/logging/__init__.py", line 1762, in callHandlers
    hdlr.handle(record)
  File "/usr/local/lib/python3.12/logging/__init__.py", line 1028, in handle
    self.emit(record)
  File "/usr/local/lib/python3.12/logging/__init__.py", line 1280, in emit
    StreamHandler.emit(self, record)
  File "/usr/local/lib/python3.12/logging/__init__.py", line 1164, in emit
    self.flush()
  File "/usr/local/lib/python3.12/logging/__init__.py", line 1144, in flush
    self.stream.flush()

2025-01-11 06:21:47,781 - INFO - Shard ID None has successfully RESUMED session 8c3fd00e15ff4035ad472de1f6aba1cc.
2025-01-11 06:24:34,033 - WARNING - Can't keep up, shard ID None websocket is 42.5s behind.
2025-01-11 06:36:18,232 - WARNING - Shard ID None has stopped responding to the gateway. Closing and restarting.
2025-01-11 06:36:53,229 - INFO - Shard ID None session has been invalidated.
2025-01-11 06:36:58,921 - INFO - Shard ID None has connected to Gateway (Session ID: e3d9c17e5d75f124a98246bfe8fc285a).
2025-01-11 06:37:08,439 - ERROR - Ignoring exception in cog unload for Cog <class 'cogs.sticky.StickyBot'> ('StickyBot')
Traceback (most recent call last):
  File "/home/container/.local/lib/python3.12/site-packages/discord/ext/commands/cog.py", line 776, in _eject
    await maybe_coroutine(self.cog_unload)
  File "/home/container/.local/lib/python3.12/site-packages/discord/utils.py", line 694, in maybe_coroutine
    return await value
           ^^^^^^^^^^^
  File "/home/container/cogs/sticky.py", line 191, in cog_unload
    await self.sticky_task
TypeError: object Loop can't be used in 'await' expression
2025-01-11 07:34:12,764 - ERROR - Ignoring exception in command None
discord.ext.commands.errors.CommandNotFound: Command "." is not found
2025-01-11 07:34:12,766 - ERROR - Ignoring exception in command None
discord.ext.commands.errors.CommandNotFound: Command "." is not found
2025-01-11 07:40:22,529 - ERROR - Ignoring exception in command None
discord.ext.commands.errors.CommandNotFound: Command "." is not found
2025-01-11 07:40:23,641 - ERROR - Ignoring exception in command None
discord.ext.commands.errors.CommandNotFound: Command ".." is not found
2025-01-11 07:40:25,949 - ERROR - Ignoring exception in command None
discord.ext.commands.errors.CommandNotFound: Command "...." is not found
2025-01-11 07:40:28,036 - ERROR - Ignoring exception in command None
discord.ext.commands.errors.CommandNotFound: Command "...................." is not found
2025-01-11 08:23:03,383 - WARNING - Can't keep up, shard ID None websocket is 41.9s behind.
2025-01-11 09:01:41,574 - INFO - Shard ID None has successfully RESUMED session e3d9c17e5d75f124a98246bfe8fc285a.
2025-01-11 09:52:11,791 - WARNING - Can't keep up, shard ID None websocket is 44.8s behind.
2025-01-11 10:17:43,051 - ERROR - Attempting a reconnect in 1.93s
Traceback (most recent call last):
  File "/home/container/.local/lib/python3.12/site-packages/discord/client.py", line 667, in connect
    await self.ws.poll_event()
  File "/home/container/.local/lib/python3.12/site-packages/discord/gateway.py", line 625, in poll_event
    await self.received_message(msg.data)
  File "/home/container/.local/lib/python3.12/site-packages/discord/gateway.py", line 533, in received_message
    await self.send_as_json(beat)
  File "/home/container/.local/lib/python3.12/site-packages/discord/gateway.py", line 661, in send_as_json
    await self.send(utils._to_json(data))
  File "/home/container/.local/lib/python3.12/site-packages/discord/gateway.py", line 657, in send
    await self.socket.send_str(data)
  File "/home/container/.local/lib/python3.12/site-packages/aiohttp/client_ws.py", line 243, in send_str
    await self._writer.send_frame(
  File "/home/container/.local/lib/python3.12/site-packages/aiohttp/_websocket/writer.py", line 125, in send_frame
    raise ClientConnectionResetError("Cannot write to closing transport")
aiohttp.client_exceptions.ClientConnectionResetError: Cannot write to closing transport
2025-01-11 10:17:43,112 - WARNING - Shard ID None heartbeat blocked for more than 10 seconds.
Loop thread traceback (most recent call last):
  File "/home/container/main.py", line 86, in <module>
    bot.run(DISCORD_TOKEN)
  File "/home/container/.local/lib/python3.12/site-packages/discord/client.py", line 869, in run
    asyncio.run(runner())
  File "/usr/local/lib/python3.12/asyncio/runners.py", line 194, in run
    return runner.run(main)
  File "/usr/local/lib/python3.12/asyncio/runners.py", line 118, in run
    return self._loop.run_until_complete(task)
  File "/usr/local/lib/python3.12/asyncio/base_events.py", line 673, in run_until_complete
    self.run_forever()
  File "/usr/local/lib/python3.12/asyncio/base_events.py", line 640, in run_forever
    self._run_once()
  File "/usr/local/lib/python3.12/asyncio/base_events.py", line 1992, in _run_once
    handle._run()
  File "/usr/local/lib/python3.12/asyncio/events.py", line 88, in _run
    self._context.run(self._callback, *self._args)
  File "/home/container/.local/lib/python3.12/site-packages/discord/ext/tasks/__init__.py", line 241, in _loop
    await self.coro(*args, **kwargs)
  File "/home/container/cogs/sticky.py", line 168, in sticky_task
    logging.error(f"Deleted previous sticky message in channel {channel_id}.")
  File "/usr/local/lib/python3.12/logging/__init__.py", line 2183, in error
    root.error(msg, *args, **kwargs)
  File "/usr/local/lib/python3.12/logging/__init__.py", line 1568, in error
    self._log(ERROR, msg, args, **kwargs)
  File "/usr/local/lib/python3.12/logging/__init__.py", line 1684, in _log
    self.handle(record)
  File "/usr/local/lib/python3.12/logging/__init__.py", line 1700, in handle
    self.callHandlers(record)
  File "/usr/local/lib/python3.12/logging/__init__.py", line 1762, in callHandlers
    hdlr.handle(record)
  File "/usr/local/lib/python3.12/logging/__init__.py", line 1028, in handle
    self.emit(record)
  File "/usr/local/lib/python3.12/logging/__init__.py", line 1280, in emit
    StreamHandler.emit(self, record)
  File "/usr/local/lib/python3.12/logging/__init__.py", line 1164, in emit
    self.flush()
  File "/usr/local/lib/python3.12/logging/__init__.py", line 1144, in flush
    self.stream.flush()

2025-01-11 10:18:07,608 - ERROR - Attempting a reconnect in 3.36s
Traceback (most recent call last):
  File "/home/container/.local/lib/python3.12/site-packages/aiohttp/connector.py", line 1351, in _create_direct_connection
    hosts = await self._resolve_host(host, port, traces=traces)
            ^^^^^^^^^^^^^^^^^^^^^^^^^^^^^^^^^^^^^^^^^^^^^^^^^^^
  File "/home/container/.local/lib/python3.12/site-packages/aiohttp/connector.py", line 995, in _resolve_host
    return await asyncio.shield(resolved_host_task)
           ^^^^^^^^^^^^^^^^^^^^^^^^^^^^^^^^^^^^^^^^
  File "/home/container/.local/lib/python3.12/site-packages/aiohttp/connector.py", line 1026, in _resolve_host_with_throttle
    addrs = await self._resolver.resolve(host, port, family=self._family)
            ^^^^^^^^^^^^^^^^^^^^^^^^^^^^^^^^^^^^^^^^^^^^^^^^^^^^^^^^^^^^^
  File "/home/container/.local/lib/python3.12/site-packages/aiohttp/resolver.py", line 36, in resolve
    infos = await self._loop.getaddrinfo(
            ^^^^^^^^^^^^^^^^^^^^^^^^^^^^^
  File "/usr/local/lib/python3.12/asyncio/base_events.py", line 900, in getaddrinfo
    return await self.run_in_executor(
           ^^^^^^^^^^^^^^^^^^^^^^^^^^^
  File "/usr/local/lib/python3.12/concurrent/futures/thread.py", line 59, in run
    result = self.fn(*self.args, **self.kwargs)
             ^^^^^^^^^^^^^^^^^^^^^^^^^^^^^^^^^^
  File "/usr/local/lib/python3.12/socket.py", line 976, in getaddrinfo
    for res in _socket.getaddrinfo(host, port, family, type, proto, flags):
               ^^^^^^^^^^^^^^^^^^^^^^^^^^^^^^^^^^^^^^^^^^^^^^^^^^^^^^^^^^^
socket.gaierror: [Errno -3] Temporary failure in name resolution

The above exception was the direct cause of the following exception:

Traceback (most recent call last):
  File "/home/container/.local/lib/python3.12/site-packages/discord/client.py", line 664, in connect
    self.ws = await asyncio.wait_for(coro, timeout=60.0)
              ^^^^^^^^^^^^^^^^^^^^^^^^^^^^^^^^^^^^^^^^^^
  File "/usr/local/lib/python3.12/asyncio/tasks.py", line 520, in wait_for
    return await fut
           ^^^^^^^^^
  File "/home/container/.local/lib/python3.12/site-packages/discord/gateway.py", line 374, in from_client
    socket = await client.http.ws_connect(str(url))
             ^^^^^^^^^^^^^^^^^^^^^^^^^^^^^^^^^^^^^^
  File "/home/container/.local/lib/python3.12/site-packages/discord/http.py", line 550, in ws_connect
    return await self.__session.ws_connect(url, **kwargs)
           ^^^^^^^^^^^^^^^^^^^^^^^^^^^^^^^^^^^^^^^^^^^^^^
  File "/home/container/.local/lib/python3.12/site-packages/aiohttp/client.py", line 1004, in _ws_connect
    resp = await self.request(
           ^^^^^^^^^^^^^^^^^^^
  File "/home/container/.local/lib/python3.12/site-packages/aiohttp/client.py", line 703, in _request
    conn = await self._connector.connect(
           ^^^^^^^^^^^^^^^^^^^^^^^^^^^^^^
  File "/home/container/.local/lib/python3.12/site-packages/aiohttp/connector.py", line 548, in connect
    proto = await self._create_connection(req, traces, timeout)
            ^^^^^^^^^^^^^^^^^^^^^^^^^^^^^^^^^^^^^^^^^^^^^^^^^^^
  File "/home/container/.local/lib/python3.12/site-packages/aiohttp/connector.py", line 1056, in _create_connection
    _, proto = await self._create_direct_connection(req, traces, timeout)
               ^^^^^^^^^^^^^^^^^^^^^^^^^^^^^^^^^^^^^^^^^^^^^^^^^^^^^^^^^^
  File "/home/container/.local/lib/python3.12/site-packages/aiohttp/connector.py", line 1357, in _create_direct_connection
    raise ClientConnectorDNSError(req.connection_key, exc) from exc
aiohttp.client_exceptions.ClientConnectorDNSError: Cannot connect to host gateway-us-east1-c.discord.gg:443 ssl:default [Temporary failure in name resolution]
2025-01-11 10:18:12,165 - INFO - Shard ID None has successfully RESUMED session e3d9c17e5d75f124a98246bfe8fc285a.
2025-01-11 10:40:17,080 - ERROR - Ignoring exception in command None
discord.ext.commands.errors.CommandNotFound: Command ".." is not found
2025-01-11 10:40:17,196 - ERROR - Ignoring exception in command None
discord.ext.commands.errors.CommandNotFound: Command ".." is not found
2025-01-11 11:43:09,920 - ERROR - Ignoring exception in command None
discord.ext.commands.errors.CommandNotFound: Command ".." is not found
2025-01-11 11:48:25,265 - ERROR - Ignoring exception in command None
discord.ext.commands.errors.CommandNotFound: Command ".." is not found
2025-01-11 11:48:25,270 - ERROR - Ignoring exception in command None
discord.ext.commands.errors.CommandNotFound: Command ".." is not found
2025-01-11 11:52:41,151 - ERROR - Ignoring exception in command None
discord.ext.commands.errors.CommandNotFound: Command "." is not found
2025-01-11 11:52:41,162 - ERROR - Ignoring exception in command None
discord.ext.commands.errors.CommandNotFound: Command "." is not found
2025-01-11 11:58:10,528 - WARNING - Shard ID None heartbeat blocked for more than 10 seconds.
Loop thread traceback (most recent call last):
  File "/home/container/main.py", line 86, in <module>
    bot.run(DISCORD_TOKEN)
  File "/home/container/.local/lib/python3.12/site-packages/discord/client.py", line 869, in run
    asyncio.run(runner())
  File "/usr/local/lib/python3.12/asyncio/runners.py", line 194, in run
    return runner.run(main)
  File "/usr/local/lib/python3.12/asyncio/runners.py", line 118, in run
    return self._loop.run_until_complete(task)
  File "/usr/local/lib/python3.12/asyncio/base_events.py", line 673, in run_until_complete
    self.run_forever()
  File "/usr/local/lib/python3.12/asyncio/base_events.py", line 640, in run_forever
    self._run_once()
  File "/usr/local/lib/python3.12/asyncio/base_events.py", line 1992, in _run_once
    handle._run()
  File "/usr/local/lib/python3.12/asyncio/events.py", line 88, in _run
    self._context.run(self._callback, *self._args)
  File "/home/container/.local/lib/python3.12/site-packages/discord/ext/tasks/__init__.py", line 241, in _loop
    await self.coro(*args, **kwargs)
  File "/home/container/cogs/sticky.py", line 176, in sticky_task
    self.save_sticky_data()
  File "/home/container/cogs/sticky.py", line 40, in save_sticky_data
    with open('sticky_data.json', 'w') as file:

2025-01-11 11:58:12,725 - ERROR - Attempting a reconnect in 0.84s
Traceback (most recent call last):
  File "/home/container/.local/lib/python3.12/site-packages/discord/client.py", line 667, in connect
    await self.ws.poll_event()
  File "/home/container/.local/lib/python3.12/site-packages/discord/gateway.py", line 625, in poll_event
    await self.received_message(msg.data)
  File "/home/container/.local/lib/python3.12/site-packages/discord/gateway.py", line 533, in received_message
    await self.send_as_json(beat)
  File "/home/container/.local/lib/python3.12/site-packages/discord/gateway.py", line 661, in send_as_json
    await self.send(utils._to_json(data))
  File "/home/container/.local/lib/python3.12/site-packages/discord/gateway.py", line 657, in send
    await self.socket.send_str(data)
  File "/home/container/.local/lib/python3.12/site-packages/aiohttp/client_ws.py", line 243, in send_str
    await self._writer.send_frame(
  File "/home/container/.local/lib/python3.12/site-packages/aiohttp/_websocket/writer.py", line 125, in send_frame
    raise ClientConnectionResetError("Cannot write to closing transport")
aiohttp.client_exceptions.ClientConnectionResetError: Cannot write to closing transport
2025-01-11 11:58:22,917 - INFO - Shard ID None has successfully RESUMED session e3d9c17e5d75f124a98246bfe8fc285a.
2025-01-11 12:21:50,880 - ERROR - Ignoring exception in command None
discord.ext.commands.errors.CommandNotFound: Command ".." is not found
2025-01-11 12:21:50,922 - ERROR - Ignoring exception in command None
discord.ext.commands.errors.CommandNotFound: Command ".." is not found
2025-01-11 12:30:06,857 - ERROR - Ignoring exception in command None
discord.ext.commands.errors.CommandNotFound: Command "..bhai" is not found
2025-01-11 12:30:06,860 - ERROR - Ignoring exception in command None
discord.ext.commands.errors.CommandNotFound: Command "..bhai" is not found
2025-01-11 12:58:12,800 - WARNING - Can't keep up, shard ID None websocket is 41.6s behind.
2025-01-11 12:59:36,383 - WARNING - Can't keep up, shard ID None websocket is 42.0s behind.
2025-01-11 13:19:26,142 - ERROR - Ignoring exception in command None
discord.ext.commands.errors.CommandNotFound: Command ".." is not found
2025-01-11 13:25:11,971 - ERROR - Ignoring exception in command None
discord.ext.commands.errors.CommandNotFound: Command "...." is not found
2025-01-11 13:25:12,006 - ERROR - Ignoring exception in command None
discord.ext.commands.errors.CommandNotFound: Command "...." is not found
2025-01-11 13:30:30,443 - ERROR - Ignoring exception in command None
discord.ext.commands.errors.CommandNotFound: Command "..." is not found
2025-01-11 13:30:31,405 - ERROR - Ignoring exception in command None
discord.ext.commands.errors.CommandNotFound: Command "..." is not found
2025-01-11 13:36:17,147 - WARNING - Shard ID None has stopped responding to the gateway. Closing and restarting.
2025-01-11 13:36:33,875 - INFO - Shard ID None session has been invalidated.
2025-01-11 13:36:39,610 - INFO - Shard ID None has connected to Gateway (Session ID: 1d74224e15dd50ca9bce07b8ed106851).
2025-01-11 13:36:44,934 - ERROR - Ignoring exception in cog unload for Cog <class 'cogs.sticky.StickyBot'> ('StickyBot')
Traceback (most recent call last):
  File "/home/container/.local/lib/python3.12/site-packages/discord/ext/commands/cog.py", line 776, in _eject
    await maybe_coroutine(self.cog_unload)
  File "/home/container/.local/lib/python3.12/site-packages/discord/utils.py", line 694, in maybe_coroutine
    return await value
           ^^^^^^^^^^^
  File "/home/container/cogs/sticky.py", line 191, in cog_unload
    await self.sticky_task
TypeError: object Loop can't be used in 'await' expression
2025-01-11 13:37:58,612 - WARNING - Can't keep up, shard ID None websocket is 43.0s behind.
2025-01-11 13:43:47,711 - ERROR - Ignoring exception in command None
discord.ext.commands.errors.CommandNotFound: Command ".." is not found
2025-01-11 13:45:10,790 - WARNING - Can't keep up, shard ID None websocket is 135.6s behind.
2025-01-11 13:45:11,173 - WARNING - Shard ID None heartbeat blocked for more than 10 seconds.
Loop thread traceback (most recent call last):
  File "/home/container/main.py", line 86, in <module>
    bot.run(DISCORD_TOKEN)
  File "/home/container/.local/lib/python3.12/site-packages/discord/client.py", line 869, in run
    asyncio.run(runner())
  File "/usr/local/lib/python3.12/asyncio/runners.py", line 194, in run
    return runner.run(main)
  File "/usr/local/lib/python3.12/asyncio/runners.py", line 118, in run
    return self._loop.run_until_complete(task)
  File "/usr/local/lib/python3.12/asyncio/base_events.py", line 673, in run_until_complete
    self.run_forever()
  File "/usr/local/lib/python3.12/asyncio/base_events.py", line 640, in run_forever
    self._run_once()
  File "/usr/local/lib/python3.12/asyncio/base_events.py", line 1992, in _run_once
    handle._run()
  File "/usr/local/lib/python3.12/asyncio/events.py", line 88, in _run
    self._context.run(self._callback, *self._args)
  File "/home/container/.local/lib/python3.12/site-packages/discord/ext/tasks/__init__.py", line 241, in _loop
    await self.coro(*args, **kwargs)
  File "/home/container/cogs/giveaway.py", line 218, in check_giveaways
    await clean_expired_giveaways()
  File "/home/container/cogs/giveaway.py", line 97, in clean_expired_giveaways
    now = datetime.utcnow().strftime(TIME_FORMAT)

2025-01-11 13:45:15,312 - ERROR - Attempting a reconnect in 0.41s
Traceback (most recent call last):
  File "/home/container/.local/lib/python3.12/site-packages/discord/client.py", line 667, in connect
    await self.ws.poll_event()
  File "/home/container/.local/lib/python3.12/site-packages/discord/gateway.py", line 625, in poll_event
    await self.received_message(msg.data)
  File "/home/container/.local/lib/python3.12/site-packages/discord/gateway.py", line 533, in received_message
    await self.send_as_json(beat)
  File "/home/container/.local/lib/python3.12/site-packages/discord/gateway.py", line 661, in send_as_json
    await self.send(utils._to_json(data))
  File "/home/container/.local/lib/python3.12/site-packages/discord/gateway.py", line 657, in send
    await self.socket.send_str(data)
  File "/home/container/.local/lib/python3.12/site-packages/aiohttp/client_ws.py", line 243, in send_str
    await self._writer.send_frame(
  File "/home/container/.local/lib/python3.12/site-packages/aiohttp/_websocket/writer.py", line 125, in send_frame
    raise ClientConnectionResetError("Cannot write to closing transport")
aiohttp.client_exceptions.ClientConnectionResetError: Cannot write to closing transport
2025-01-11 13:45:16,036 - ERROR - Ignoring exception in command None
discord.ext.commands.errors.CommandNotFound: Command "." is not found
2025-01-11 13:45:16,178 - ERROR - Ignoring exception in command None
discord.ext.commands.errors.CommandNotFound: Command "." is not found
2025-01-11 13:45:24,805 - INFO - Shard ID None has successfully RESUMED session 1d74224e15dd50ca9bce07b8ed106851.
2025-01-11 14:26:19,086 - INFO - Shard ID None has successfully RESUMED session 1d74224e15dd50ca9bce07b8ed106851.
2025-01-11 15:51:00,232 - ERROR - Ignoring exception in command None
discord.ext.commands.errors.CommandNotFound: Command ".really….??" is not found
2025-01-11 15:51:00,234 - ERROR - Ignoring exception in command None
discord.ext.commands.errors.CommandNotFound: Command ".really….??" is not found
2025-01-11 16:20:29,651 - ERROR - Ignoring exception in command None
discord.ext.commands.errors.CommandNotFound: Command ".." is not found
2025-01-11 16:20:29,652 - ERROR - Ignoring exception in command None
discord.ext.commands.errors.CommandNotFound: Command ".." is not found
2025-01-11 17:24:54,213 - ERROR - Ignoring exception in command None
discord.ext.commands.errors.CommandNotFound: Command ".." is not found
2025-01-11 17:43:52,986 - INFO - Shard ID None has successfully RESUMED session 1d74224e15dd50ca9bce07b8ed106851.
2025-01-11 17:53:01,090 - INFO - Shard ID None has successfully RESUMED session 1d74224e15dd50ca9bce07b8ed106851.
2025-01-11 17:58:16,439 - ERROR - Ignoring exception in command None
discord.ext.commands.errors.CommandNotFound: Command ".." is not found
2025-01-11 17:58:16,440 - ERROR - Ignoring exception in command None
discord.ext.commands.errors.CommandNotFound: Command ".." is not found
2025-01-11 17:59:04,990 - ERROR - Ignoring exception in command None
discord.ext.commands.errors.CommandNotFound: Command ".." is not found
2025-01-11 17:59:04,992 - ERROR - Ignoring exception in command None
discord.ext.commands.errors.CommandNotFound: Command ".." is not found
2025-01-11 18:04:12,874 - ERROR - Ignoring exception in command None
discord.ext.commands.errors.CommandNotFound: Command "snipe" is not found
2025-01-11 18:10:39,335 - INFO - Shard ID None has successfully RESUMED session 1d74224e15dd50ca9bce07b8ed106851.
2025-01-11 18:29:00,521 - INFO - Shard ID None has successfully RESUMED session 1d74224e15dd50ca9bce07b8ed106851.
2025-01-11 19:15:12,474 - ERROR - Ignoring exception in command None
discord.ext.commands.errors.CommandNotFound: Command "." is not found
2025-01-11 19:19:16,523 - INFO - Shard ID None has successfully RESUMED session 1d74224e15dd50ca9bce07b8ed106851.
2025-01-11 19:27:40,900 - ERROR - Ignoring exception in command None
discord.ext.commands.errors.CommandNotFound: Command ".." is not found
2025-01-11 19:27:40,901 - ERROR - Ignoring exception in command None
discord.ext.commands.errors.CommandNotFound: Command ".." is not found
2025-01-11 19:37:10,888 - ERROR - Ignoring exception in command None
discord.ext.commands.errors.CommandNotFound: Command "s" is not found
2025-01-11 19:56:25,827 - ERROR - Ignoring exception in command None
discord.ext.commands.errors.CommandNotFound: Command "." is not found
2025-01-11 19:56:25,830 - ERROR - Ignoring exception in command None
discord.ext.commands.errors.CommandNotFound: Command "." is not found
2025-01-11 19:56:52,531 - ERROR - Ignoring exception in command None
discord.ext.commands.errors.CommandNotFound: Command "." is not found
2025-01-11 20:13:31,518 - ERROR - Ignoring exception in command None
discord.ext.commands.errors.CommandNotFound: Command "kutti" is not found
2025-01-11 20:13:31,519 - ERROR - Ignoring exception in command None
discord.ext.commands.errors.CommandNotFound: Command "kutti" is not found
2025-01-11 20:55:42,170 - ERROR - Ignoring exception in command None
discord.ext.commands.errors.CommandNotFound: Command "." is not found
2025-01-11 20:55:46,777 - ERROR - Ignoring exception in command None
discord.ext.commands.errors.CommandNotFound: Command ".." is not found
2025-01-11 20:55:49,436 - ERROR - Ignoring exception in command None
discord.ext.commands.errors.CommandNotFound: Command "..." is not found
2025-01-11 20:55:51,751 - ERROR - Ignoring exception in command None
discord.ext.commands.errors.CommandNotFound: Command "....." is not found
2025-01-11 20:55:55,373 - ERROR - Ignoring exception in command None
discord.ext.commands.errors.CommandNotFound: Command "......" is not found
2025-01-11 20:55:57,522 - ERROR - Ignoring exception in command None
discord.ext.commands.errors.CommandNotFound: Command "............." is not found
2025-01-11 20:55:59,359 - ERROR - Ignoring exception in command None
discord.ext.commands.errors.CommandNotFound: Command "............." is not found
2025-01-11 20:56:08,364 - ERROR - Ignoring exception in command None
discord.ext.commands.errors.CommandNotFound: Command "...." is not found
2025-01-11 21:08:11,049 - ERROR - Ignoring exception in command None
discord.ext.commands.errors.CommandNotFound: Command ".." is not found
2025-01-11 21:49:50,925 - ERROR - Ignoring exception in command None
discord.ext.commands.errors.CommandNotFound: Command "." is not found
2025-01-11 22:05:34,990 - ERROR - Ignoring exception in command None
discord.ext.commands.errors.CommandNotFound: Command "Maa" is not found
2025-01-11 22:05:34,991 - ERROR - Ignoring exception in command None
discord.ext.commands.errors.CommandNotFound: Command "Maa" is not found
2025-01-11 22:30:07,435 - ERROR - Ignoring exception in command None
discord.ext.commands.errors.CommandNotFound: Command "." is not found
2025-01-11 23:02:08,889 - ERROR - Ignoring exception in command None
discord.ext.commands.errors.CommandNotFound: Command "." is not found
2025-01-11 23:02:08,891 - ERROR - Ignoring exception in command None
discord.ext.commands.errors.CommandNotFound: Command "." is not found
2025-01-11 23:20:52,756 - INFO - Shard ID None has successfully RESUMED session 2e1b4a2f7591a9fae3161b788699ad75.
2025-01-11 23:39:17,295 - ERROR - Ignoring exception in command None
discord.ext.commands.errors.CommandNotFound: Command "32=]-[0P90I-" is not found
2025-01-12 00:40:32,527 - INFO - Shard ID None has successfully RESUMED session 2e1b4a2f7591a9fae3161b788699ad75.
2025-01-12 01:19:51,342 - ERROR - Ignoring exception in command None
discord.ext.commands.errors.CommandNotFound: Command "." is not found
2025-01-12 01:19:53,103 - ERROR - Ignoring exception in command None
discord.ext.commands.errors.CommandNotFound: Command ".." is not found
2025-01-12 01:19:54,456 - ERROR - Ignoring exception in command None
discord.ext.commands.errors.CommandNotFound: Command "..." is not found
2025-01-12 01:19:56,089 - ERROR - Ignoring exception in command None
discord.ext.commands.errors.CommandNotFound: Command "......" is not found
2025-01-12 01:20:00,073 - ERROR - Ignoring exception in command None
discord.ext.commands.errors.CommandNotFound: Command ".........." is not found
2025-01-12 04:21:00,210 - INFO - Shard ID None has successfully RESUMED session 2e1b4a2f7591a9fae3161b788699ad75.
2025-01-12 06:08:59,957 - WARNING - Can't keep up, shard ID None websocket is 43.3s behind.
2025-01-12 06:09:50,001 - WARNING - Can't keep up, shard ID None websocket is 50.0s behind.
2025-01-12 06:59:52,912 - INFO - Shard ID None has successfully RESUMED session 2e1b4a2f7591a9fae3161b788699ad75.
2025-01-12 07:15:50,476 - ERROR - Attempting a reconnect in 1.75s
Traceback (most recent call last):
  File "/home/container/.local/lib/python3.12/site-packages/discord/client.py", line 667, in connect
    await self.ws.poll_event()
  File "/home/container/.local/lib/python3.12/site-packages/discord/gateway.py", line 648, in poll_event
    raise ConnectionClosed(self.socket, shard_id=self.shard_id, code=code) from None
discord.errors.ConnectionClosed: Shard ID None WebSocket closed with 1000
2025-01-12 07:15:54,740 - WARNING - Shard ID None heartbeat blocked for more than 10 seconds.
Loop thread traceback (most recent call last):
  File "/home/container/main.py", line 86, in <module>
    bot.run(DISCORD_TOKEN)
  File "/home/container/.local/lib/python3.12/site-packages/discord/client.py", line 869, in run
    asyncio.run(runner())
  File "/usr/local/lib/python3.12/asyncio/runners.py", line 194, in run
    return runner.run(main)
  File "/usr/local/lib/python3.12/asyncio/runners.py", line 118, in run
    return self._loop.run_until_complete(task)
  File "/usr/local/lib/python3.12/asyncio/base_events.py", line 673, in run_until_complete
    self.run_forever()
  File "/usr/local/lib/python3.12/asyncio/base_events.py", line 640, in run_forever
    self._run_once()
  File "/usr/local/lib/python3.12/asyncio/base_events.py", line 1992, in _run_once
    handle._run()
  File "/usr/local/lib/python3.12/asyncio/events.py", line 88, in _run
    self._context.run(self._callback, *self._args)
  File "/home/container/.local/lib/python3.12/site-packages/discord/client.py", line 858, in runner
    await self.start(token, reconnect=reconnect)
  File "/home/container/.local/lib/python3.12/site-packages/discord/client.py", line 787, in start
    await self.connect(reconnect=reconnect)
  File "/home/container/.local/lib/python3.12/site-packages/discord/client.py", line 667, in connect
    await self.ws.poll_event()
  File "/home/container/.local/lib/python3.12/site-packages/discord/gateway.py", line 625, in poll_event
    await self.received_message(msg.data)
  File "/home/container/.local/lib/python3.12/site-packages/discord/gateway.py", line 575, in received_message
    func(data)
  File "/home/container/.local/lib/python3.12/site-packages/discord/state.py", line 657, in parse_message_create
    self.dispatch('message', message)
  File "/home/container/.local/lib/python3.12/site-packages/discord/ext/commands/bot.py", line 231, in dispatch
    self._schedule_event(event, ev, *args, **kwargs)  # type: ignore
  File "/home/container/.local/lib/python3.12/site-packages/discord/client.py", line 465, in _schedule_event
    wrapped = self._run_event(coro, event_name, *args, **kwargs)

2025-01-12 07:16:01,022 - INFO - Shard ID None has successfully RESUMED session 2e1b4a2f7591a9fae3161b788699ad75.
2025-01-12 07:27:10,044 - ERROR - Ignoring exception in command None
discord.ext.commands.errors.CommandNotFound: Command "gaming" is not found
2025-01-12 07:27:10,045 - ERROR - Ignoring exception in command None
discord.ext.commands.errors.CommandNotFound: Command "gaming" is not found
2025-01-12 08:32:47,623 - ERROR - Ignoring exception in command None
discord.ext.commands.errors.CommandNotFound: Command "." is not found
2025-01-12 08:32:47,623 - ERROR - Ignoring exception in command None
discord.ext.commands.errors.CommandNotFound: Command "." is not found
2025-01-12 08:33:01,905 - ERROR - Ignoring exception in command None
discord.ext.commands.errors.CommandNotFound: Command ".." is not found
2025-01-12 08:33:01,906 - ERROR - Ignoring exception in command None
discord.ext.commands.errors.CommandNotFound: Command ".." is not found
2025-01-12 10:21:39,687 - INFO - Shard ID None has successfully RESUMED session 2e1b4a2f7591a9fae3161b788699ad75.
2025-01-12 10:55:34,803 - ERROR - Ignoring exception in command None
discord.ext.commands.errors.CommandNotFound: Command "verify" is not found
2025-01-12 10:56:18,708 - ERROR - Ignoring exception in command None
discord.ext.commands.errors.CommandNotFound: Command "staff" is not found
2025-01-12 10:56:18,711 - ERROR - Ignoring exception in command None
discord.ext.commands.errors.CommandNotFound: Command "staff" is not found
2025-01-12 11:12:02,432 - ERROR - Ignoring exception in command None
discord.ext.commands.errors.CommandNotFound: Command ".../ᐠ｡ꞈ｡ᐟ\" is not found
2025-01-12 11:22:00,226 - ERROR - Ignoring exception in command None
discord.ext.commands.errors.CommandNotFound: Command "." is not found
2025-01-12 11:22:00,228 - ERROR - Ignoring exception in command None
discord.ext.commands.errors.CommandNotFound: Command "." is not found
2025-01-12 11:29:19,367 - INFO - Shard ID None has successfully RESUMED session 2e1b4a2f7591a9fae3161b788699ad75.
2025-01-12 12:45:33,942 - INFO - Shard ID None has successfully RESUMED session 2e1b4a2f7591a9fae3161b788699ad75.
2025-01-12 14:30:01,102 - INFO - Shard ID None has successfully RESUMED session 2e1b4a2f7591a9fae3161b788699ad75.
2025-01-12 14:30:51,906 - ERROR - Ignoring exception in command None
discord.ext.commands.errors.CommandNotFound: Command ".." is not found
2025-01-12 14:42:41,846 - ERROR - Ignoring exception in command None
discord.ext.commands.errors.CommandNotFound: Command "..." is not found
2025-01-12 14:45:54,608 - ERROR - Ignoring exception in command None
discord.ext.commands.errors.CommandNotFound: Command "..." is not found
2025-01-12 14:48:53,384 - ERROR - Ignoring exception in command None
discord.ext.commands.errors.CommandNotFound: Command "." is not found
2025-01-12 14:50:24,501 - ERROR - Ignoring exception in command None
discord.ext.commands.errors.CommandNotFound: Command "." is not found
2025-01-12 15:07:35,888 - ERROR - Attempting a reconnect in 1.63s
Traceback (most recent call last):
  File "/home/container/.local/lib/python3.12/site-packages/discord/client.py", line 667, in connect
    await self.ws.poll_event()
  File "/home/container/.local/lib/python3.12/site-packages/discord/gateway.py", line 625, in poll_event
    await self.received_message(msg.data)
  File "/home/container/.local/lib/python3.12/site-packages/discord/gateway.py", line 533, in received_message
    await self.send_as_json(beat)
  File "/home/container/.local/lib/python3.12/site-packages/discord/gateway.py", line 661, in send_as_json
    await self.send(utils._to_json(data))
  File "/home/container/.local/lib/python3.12/site-packages/discord/gateway.py", line 657, in send
    await self.socket.send_str(data)
  File "/home/container/.local/lib/python3.12/site-packages/aiohttp/client_ws.py", line 243, in send_str
    await self._writer.send_frame(
  File "/home/container/.local/lib/python3.12/site-packages/aiohttp/_websocket/writer.py", line 125, in send_frame
    raise ClientConnectionResetError("Cannot write to closing transport")
aiohttp.client_exceptions.ClientConnectionResetError: Cannot write to closing transport
2025-01-12 15:07:43,252 - WARNING - Shard ID None heartbeat blocked for more than 10 seconds.
Loop thread traceback (most recent call last):
  File "/home/container/main.py", line 86, in <module>
    bot.run(DISCORD_TOKEN)
  File "/home/container/.local/lib/python3.12/site-packages/discord/client.py", line 869, in run
    asyncio.run(runner())
  File "/usr/local/lib/python3.12/asyncio/runners.py", line 194, in run
    return runner.run(main)
  File "/usr/local/lib/python3.12/asyncio/runners.py", line 118, in run
    return self._loop.run_until_complete(task)
  File "/usr/local/lib/python3.12/asyncio/base_events.py", line 673, in run_until_complete
    self.run_forever()
  File "/usr/local/lib/python3.12/asyncio/base_events.py", line 640, in run_forever
    self._run_once()
  File "/usr/local/lib/python3.12/asyncio/base_events.py", line 1992, in _run_once
    handle._run()
  File "/usr/local/lib/python3.12/asyncio/events.py", line 88, in _run
    self._context.run(self._callback, *self._args)
  File "/home/container/.local/lib/python3.12/site-packages/discord/client.py", line 858, in runner
    await self.start(token, reconnect=reconnect)
  File "/home/container/.local/lib/python3.12/site-packages/discord/client.py", line 787, in start
    await self.connect(reconnect=reconnect)
  File "/home/container/.local/lib/python3.12/site-packages/discord/client.py", line 667, in connect
    await self.ws.poll_event()
  File "/home/container/.local/lib/python3.12/site-packages/discord/gateway.py", line 625, in poll_event
    await self.received_message(msg.data)
  File "/home/container/.local/lib/python3.12/site-packages/discord/gateway.py", line 575, in received_message
    func(data)
  File "/home/container/.local/lib/python3.12/site-packages/discord/state.py", line 1603, in parse_typing_start
    raw = RawTypingEvent(data)
  File "/home/container/.local/lib/python3.12/site-packages/discord/raw_models.py", line 478, in __init__
    self.timestamp: datetime.datetime = datetime.datetime.fromtimestamp(data['timestamp'], tz=datetime.timezone.utc)

2025-01-12 15:07:51,679 - INFO - Shard ID None has successfully RESUMED session 2e1b4a2f7591a9fae3161b788699ad75.
2025-01-12 15:29:19,027 - INFO - Shard ID None has successfully RESUMED session 2e1b4a2f7591a9fae3161b788699ad75.
2025-01-12 15:43:00,906 - ERROR - Ignoring exception in command None
discord.ext.commands.errors.CommandNotFound: Command "....." is not found
2025-01-12 15:54:11,952 - ERROR - Ignoring exception in command None
discord.ext.commands.errors.CommandNotFound: Command "." is not found
2025-01-12 16:41:49,999 - WARNING - Shard ID None heartbeat blocked for more than 10 seconds.
Loop thread traceback (most recent call last):
  File "/home/container/main.py", line 86, in <module>
    bot.run(DISCORD_TOKEN)
  File "/home/container/.local/lib/python3.12/site-packages/discord/client.py", line 869, in run
    asyncio.run(runner())
  File "/usr/local/lib/python3.12/asyncio/runners.py", line 194, in run
    return runner.run(main)
  File "/usr/local/lib/python3.12/asyncio/runners.py", line 118, in run
    return self._loop.run_until_complete(task)
  File "/usr/local/lib/python3.12/asyncio/base_events.py", line 673, in run_until_complete
    self.run_forever()
  File "/usr/local/lib/python3.12/asyncio/base_events.py", line 640, in run_forever
    self._run_once()
  File "/usr/local/lib/python3.12/asyncio/base_events.py", line 1992, in _run_once
    handle._run()
  File "/usr/local/lib/python3.12/asyncio/events.py", line 88, in _run
    self._context.run(self._callback, *self._args)
  File "/home/container/.local/lib/python3.12/site-packages/discord/ext/tasks/__init__.py", line 241, in _loop
    await self.coro(*args, **kwargs)
  File "/home/container/cogs/sticky.py", line 176, in sticky_task
    self.save_sticky_data()
  File "/home/container/cogs/sticky.py", line 40, in save_sticky_data
    with open('sticky_data.json', 'w') as file:

2025-01-12 16:47:21,754 - WARNING - Can't keep up, shard ID None websocket is 41.8s behind.
2025-01-12 16:49:29,420 - WARNING - Can't keep up, shard ID None websocket is 41.6s behind.
2025-01-12 17:42:13,560 - ERROR - Ignoring exception in command None
discord.ext.commands.errors.CommandNotFound: Command "..no" is not found
2025-01-12 17:42:13,636 - ERROR - Ignoring exception in command None
discord.ext.commands.errors.CommandNotFound: Command "..no" is not found
2025-01-12 18:00:57,022 - WARNING - Shard ID None has stopped responding to the gateway. Closing and restarting.
2025-01-12 18:00:57,790 - WARNING - Can't keep up, shard ID None websocket is 44.2s behind.
2025-01-12 18:01:01,692 - ERROR - Attempting a reconnect in 1.55s
Traceback (most recent call last):
  File "/home/container/.local/lib/python3.12/site-packages/discord/client.py", line 667, in connect
    await self.ws.poll_event()
  File "/home/container/.local/lib/python3.12/site-packages/discord/gateway.py", line 648, in poll_event
    raise ConnectionClosed(self.socket, shard_id=self.shard_id, code=code) from None
discord.errors.ConnectionClosed: Shard ID None WebSocket closed with 1000
2025-01-12 18:01:10,026 - INFO - Shard ID None has successfully RESUMED session 2e1b4a2f7591a9fae3161b788699ad75.
2025-01-12 18:01:53,370 - WARNING - Can't keep up, shard ID None websocket is 43.6s behind.
2025-01-12 18:05:21,420 - WARNING - Can't keep up, shard ID None websocket is 42.9s behind.
2025-01-12 18:38:50,399 - ERROR - Attempting a reconnect in 0.15s
Traceback (most recent call last):
  File "/home/container/.local/lib/python3.12/site-packages/discord/client.py", line 667, in connect
    await self.ws.poll_event()
  File "/home/container/.local/lib/python3.12/site-packages/discord/gateway.py", line 625, in poll_event
    await self.received_message(msg.data)
  File "/home/container/.local/lib/python3.12/site-packages/discord/gateway.py", line 533, in received_message
    await self.send_as_json(beat)
  File "/home/container/.local/lib/python3.12/site-packages/discord/gateway.py", line 661, in send_as_json
    await self.send(utils._to_json(data))
  File "/home/container/.local/lib/python3.12/site-packages/discord/gateway.py", line 657, in send
    await self.socket.send_str(data)
  File "/home/container/.local/lib/python3.12/site-packages/aiohttp/client_ws.py", line 243, in send_str
    await self._writer.send_frame(
  File "/home/container/.local/lib/python3.12/site-packages/aiohttp/_websocket/writer.py", line 125, in send_frame
    raise ClientConnectionResetError("Cannot write to closing transport")
aiohttp.client_exceptions.ClientConnectionResetError: Cannot write to closing transport
2025-01-12 18:39:25,330 - INFO - Shard ID None session has been invalidated.
2025-01-12 18:39:30,919 - INFO - Shard ID None has connected to Gateway (Session ID: 9e8b91161ce3be3e44ebf079ab66e261).
2025-01-12 18:39:37,385 - ERROR - Ignoring exception in cog unload for Cog <class 'cogs.sticky.StickyBot'> ('StickyBot')
Traceback (most recent call last):
  File "/home/container/.local/lib/python3.12/site-packages/discord/ext/commands/cog.py", line 776, in _eject
    await maybe_coroutine(self.cog_unload)
  File "/home/container/.local/lib/python3.12/site-packages/discord/utils.py", line 694, in maybe_coroutine
    return await value
           ^^^^^^^^^^^
  File "/home/container/cogs/sticky.py", line 191, in cog_unload
    await self.sticky_task
TypeError: object Loop can't be used in 'await' expression
2025-01-12 18:44:12,456 - ERROR - Ignoring exception in command None
discord.ext.commands.errors.CommandNotFound: Command ".." is not found
2025-01-12 18:54:37,971 - WARNING - Can't keep up, shard ID None websocket is 41.6s behind.
2025-01-12 19:17:50,566 - INFO - Shard ID None has successfully RESUMED session 9e8b91161ce3be3e44ebf079ab66e261.
2025-01-12 19:37:50,472 - WARNING - Can't keep up, shard ID None websocket is 41.5s behind.
2025-01-12 19:51:45,674 - ERROR - Ignoring exception in view <DragmeButtons timeout=30 children=2> for item <Button style=<ButtonStyle.success: 3> url=None disabled=False label='' emoji=<PartialEmoji animated=False name='sukoon_tick' id=1321088727912808469> row=None sku_id=None>
Traceback (most recent call last):
  File "/home/container/cogs/dragmee.py", line 64, in accept_button
    await interaction.response.send_message(f"<a:sukoon_greendot:1322894177775783997> {self.interaction_user.mention} has been moved to {self.target_voice_channel.name}.")
  File "/home/container/.local/lib/python3.12/site-packages/discord/interactions.py", line 855, in send_message
    await adapter.create_interaction_response(
  File "/home/container/.local/lib/python3.12/site-packages/discord/webhook/async_.py", line 221, in request
    raise NotFound(response, data)
discord.errors.NotFound: 404 Not Found (error code: 10062): Unknown interaction

During handling of the above exception, another exception occurred:

Traceback (most recent call last):
  File "/home/container/.local/lib/python3.12/site-packages/discord/ui/view.py", line 430, in _scheduled_task
    await item.callback(interaction)
  File "/home/container/cogs/dragmee.py", line 74, in accept_button
    await interaction.response.send_message("There was an error processing the move.", ephemeral=True)
  File "/home/container/.local/lib/python3.12/site-packages/discord/interactions.py", line 855, in send_message
    await adapter.create_interaction_response(
  File "/home/container/.local/lib/python3.12/site-packages/discord/webhook/async_.py", line 221, in request
    raise NotFound(response, data)
discord.errors.NotFound: 404 Not Found (error code: 10062): Unknown interaction
2025-01-12 19:52:05,269 - ERROR - Ignoring exception in view <DragmeButtons timeout=30 children=2> for item <Button style=<ButtonStyle.success: 3> url=None disabled=False label='' emoji=<PartialEmoji animated=False name='sukoon_tick' id=1321088727912808469> row=None sku_id=None>
Traceback (most recent call last):
  File "/home/container/cogs/dragmee.py", line 64, in accept_button
    await interaction.response.send_message(f"<a:sukoon_greendot:1322894177775783997> {self.interaction_user.mention} has been moved to {self.target_voice_channel.name}.")
  File "/home/container/.local/lib/python3.12/site-packages/discord/interactions.py", line 855, in send_message
    await adapter.create_interaction_response(
  File "/home/container/.local/lib/python3.12/site-packages/discord/webhook/async_.py", line 221, in request
    raise NotFound(response, data)
discord.errors.NotFound: 404 Not Found (error code: 10062): Unknown interaction

During handling of the above exception, another exception occurred:

Traceback (most recent call last):
  File "/home/container/.local/lib/python3.12/site-packages/discord/ui/view.py", line 430, in _scheduled_task
    await item.callback(interaction)
  File "/home/container/cogs/dragmee.py", line 74, in accept_button
    await interaction.response.send_message("There was an error processing the move.", ephemeral=True)
  File "/home/container/.local/lib/python3.12/site-packages/discord/interactions.py", line 855, in send_message
    await adapter.create_interaction_response(
  File "/home/container/.local/lib/python3.12/site-packages/discord/webhook/async_.py", line 221, in request
    raise NotFound(response, data)
discord.errors.NotFound: 404 Not Found (error code: 10062): Unknown interaction
2025-01-12 19:52:34,591 - WARNING - Shard ID None heartbeat blocked for more than 10 seconds.
Loop thread traceback (most recent call last):
  File "/home/container/main.py", line 86, in <module>
    bot.run(DISCORD_TOKEN)
  File "/home/container/.local/lib/python3.12/site-packages/discord/client.py", line 869, in run
    asyncio.run(runner())
  File "/usr/local/lib/python3.12/asyncio/runners.py", line 194, in run
    return runner.run(main)
  File "/usr/local/lib/python3.12/asyncio/runners.py", line 118, in run
    return self._loop.run_until_complete(task)
  File "/usr/local/lib/python3.12/asyncio/base_events.py", line 673, in run_until_complete
    self.run_forever()
  File "/usr/local/lib/python3.12/asyncio/base_events.py", line 640, in run_forever
    self._run_once()
  File "/usr/local/lib/python3.12/asyncio/base_events.py", line 1992, in _run_once
    handle._run()
  File "/usr/local/lib/python3.12/asyncio/events.py", line 88, in _run
    self._context.run(self._callback, *self._args)
  File "/home/container/.local/lib/python3.12/site-packages/discord/client.py", line 449, in _run_event
    await coro(*args, **kwargs)
  File "/home/container/cogs/sticky.py", line 132, in on_message
    logging.error(f"Deleted previous sticky message with ID: {last_message_id}")
  File "/usr/local/lib/python3.12/logging/__init__.py", line 2183, in error
    root.error(msg, *args, **kwargs)
  File "/usr/local/lib/python3.12/logging/__init__.py", line 1568, in error
    self._log(ERROR, msg, args, **kwargs)
  File "/usr/local/lib/python3.12/logging/__init__.py", line 1684, in _log
    self.handle(record)
  File "/usr/local/lib/python3.12/logging/__init__.py", line 1700, in handle
    self.callHandlers(record)
  File "/usr/local/lib/python3.12/logging/__init__.py", line 1762, in callHandlers
    hdlr.handle(record)
  File "/usr/local/lib/python3.12/logging/__init__.py", line 1028, in handle
    self.emit(record)
  File "/usr/local/lib/python3.12/logging/__init__.py", line 1280, in emit
    StreamHandler.emit(self, record)
  File "/usr/local/lib/python3.12/logging/__init__.py", line 1164, in emit
    self.flush()
  File "/usr/local/lib/python3.12/logging/__init__.py", line 1144, in flush
    self.stream.flush()

2025-01-12 19:53:39,844 - ERROR - Attempting a reconnect in 1.94s
Traceback (most recent call last):
  File "/home/container/.local/lib/python3.12/site-packages/aiohttp/connector.py", line 1351, in _create_direct_connection
    hosts = await self._resolve_host(host, port, traces=traces)
            ^^^^^^^^^^^^^^^^^^^^^^^^^^^^^^^^^^^^^^^^^^^^^^^^^^^
  File "/home/container/.local/lib/python3.12/site-packages/aiohttp/connector.py", line 995, in _resolve_host
    return await asyncio.shield(resolved_host_task)
           ^^^^^^^^^^^^^^^^^^^^^^^^^^^^^^^^^^^^^^^^
  File "/home/container/.local/lib/python3.12/site-packages/aiohttp/connector.py", line 1026, in _resolve_host_with_throttle
    addrs = await self._resolver.resolve(host, port, family=self._family)
            ^^^^^^^^^^^^^^^^^^^^^^^^^^^^^^^^^^^^^^^^^^^^^^^^^^^^^^^^^^^^^
  File "/home/container/.local/lib/python3.12/site-packages/aiohttp/resolver.py", line 36, in resolve
    infos = await self._loop.getaddrinfo(
            ^^^^^^^^^^^^^^^^^^^^^^^^^^^^^
  File "/usr/local/lib/python3.12/asyncio/base_events.py", line 900, in getaddrinfo
    return await self.run_in_executor(
           ^^^^^^^^^^^^^^^^^^^^^^^^^^^
  File "/usr/local/lib/python3.12/concurrent/futures/thread.py", line 59, in run
    result = self.fn(*self.args, **self.kwargs)
             ^^^^^^^^^^^^^^^^^^^^^^^^^^^^^^^^^^
  File "/usr/local/lib/python3.12/socket.py", line 976, in getaddrinfo
    for res in _socket.getaddrinfo(host, port, family, type, proto, flags):
               ^^^^^^^^^^^^^^^^^^^^^^^^^^^^^^^^^^^^^^^^^^^^^^^^^^^^^^^^^^^
socket.gaierror: [Errno -3] Temporary failure in name resolution

The above exception was the direct cause of the following exception:

Traceback (most recent call last):
  File "/home/container/.local/lib/python3.12/site-packages/discord/client.py", line 664, in connect
    self.ws = await asyncio.wait_for(coro, timeout=60.0)
              ^^^^^^^^^^^^^^^^^^^^^^^^^^^^^^^^^^^^^^^^^^
  File "/usr/local/lib/python3.12/asyncio/tasks.py", line 520, in wait_for
    return await fut
           ^^^^^^^^^
  File "/home/container/.local/lib/python3.12/site-packages/discord/gateway.py", line 374, in from_client
    socket = await client.http.ws_connect(str(url))
             ^^^^^^^^^^^^^^^^^^^^^^^^^^^^^^^^^^^^^^
  File "/home/container/.local/lib/python3.12/site-packages/discord/http.py", line 550, in ws_connect
    return await self.__session.ws_connect(url, **kwargs)
           ^^^^^^^^^^^^^^^^^^^^^^^^^^^^^^^^^^^^^^^^^^^^^^
  File "/home/container/.local/lib/python3.12/site-packages/aiohttp/client.py", line 1004, in _ws_connect
    resp = await self.request(
           ^^^^^^^^^^^^^^^^^^^
  File "/home/container/.local/lib/python3.12/site-packages/aiohttp/client.py", line 703, in _request
    conn = await self._connector.connect(
           ^^^^^^^^^^^^^^^^^^^^^^^^^^^^^^
  File "/home/container/.local/lib/python3.12/site-packages/aiohttp/connector.py", line 548, in connect
    proto = await self._create_connection(req, traces, timeout)
            ^^^^^^^^^^^^^^^^^^^^^^^^^^^^^^^^^^^^^^^^^^^^^^^^^^^
  File "/home/container/.local/lib/python3.12/site-packages/aiohttp/connector.py", line 1056, in _create_connection
    _, proto = await self._create_direct_connection(req, traces, timeout)
               ^^^^^^^^^^^^^^^^^^^^^^^^^^^^^^^^^^^^^^^^^^^^^^^^^^^^^^^^^^
  File "/home/container/.local/lib/python3.12/site-packages/aiohttp/connector.py", line 1357, in _create_direct_connection
    raise ClientConnectorDNSError(req.connection_key, exc) from exc
aiohttp.client_exceptions.ClientConnectorDNSError: Cannot connect to host gateway-us-east1-c.discord.gg:443 ssl:default [Temporary failure in name resolution]
2025-01-12 19:54:02,318 - ERROR - Attempting a reconnect in 1.08s
Traceback (most recent call last):
  File "/home/container/.local/lib/python3.12/site-packages/aiohttp/connector.py", line 1351, in _create_direct_connection
    hosts = await self._resolve_host(host, port, traces=traces)
            ^^^^^^^^^^^^^^^^^^^^^^^^^^^^^^^^^^^^^^^^^^^^^^^^^^^
  File "/home/container/.local/lib/python3.12/site-packages/aiohttp/connector.py", line 995, in _resolve_host
    return await asyncio.shield(resolved_host_task)
           ^^^^^^^^^^^^^^^^^^^^^^^^^^^^^^^^^^^^^^^^
  File "/home/container/.local/lib/python3.12/site-packages/aiohttp/connector.py", line 1026, in _resolve_host_with_throttle
    addrs = await self._resolver.resolve(host, port, family=self._family)
            ^^^^^^^^^^^^^^^^^^^^^^^^^^^^^^^^^^^^^^^^^^^^^^^^^^^^^^^^^^^^^
  File "/home/container/.local/lib/python3.12/site-packages/aiohttp/resolver.py", line 36, in resolve
    infos = await self._loop.getaddrinfo(
            ^^^^^^^^^^^^^^^^^^^^^^^^^^^^^
  File "/usr/local/lib/python3.12/asyncio/base_events.py", line 900, in getaddrinfo
    return await self.run_in_executor(
           ^^^^^^^^^^^^^^^^^^^^^^^^^^^
  File "/usr/local/lib/python3.12/concurrent/futures/thread.py", line 59, in run
    result = self.fn(*self.args, **self.kwargs)
             ^^^^^^^^^^^^^^^^^^^^^^^^^^^^^^^^^^
  File "/usr/local/lib/python3.12/socket.py", line 976, in getaddrinfo
    for res in _socket.getaddrinfo(host, port, family, type, proto, flags):
               ^^^^^^^^^^^^^^^^^^^^^^^^^^^^^^^^^^^^^^^^^^^^^^^^^^^^^^^^^^^
socket.gaierror: [Errno -3] Temporary failure in name resolution

The above exception was the direct cause of the following exception:

Traceback (most recent call last):
  File "/home/container/.local/lib/python3.12/site-packages/discord/client.py", line 664, in connect
    self.ws = await asyncio.wait_for(coro, timeout=60.0)
              ^^^^^^^^^^^^^^^^^^^^^^^^^^^^^^^^^^^^^^^^^^
  File "/usr/local/lib/python3.12/asyncio/tasks.py", line 520, in wait_for
    return await fut
           ^^^^^^^^^
  File "/home/container/.local/lib/python3.12/site-packages/discord/gateway.py", line 374, in from_client
    socket = await client.http.ws_connect(str(url))
             ^^^^^^^^^^^^^^^^^^^^^^^^^^^^^^^^^^^^^^
  File "/home/container/.local/lib/python3.12/site-packages/discord/http.py", line 550, in ws_connect
    return await self.__session.ws_connect(url, **kwargs)
           ^^^^^^^^^^^^^^^^^^^^^^^^^^^^^^^^^^^^^^^^^^^^^^
  File "/home/container/.local/lib/python3.12/site-packages/aiohttp/client.py", line 1004, in _ws_connect
    resp = await self.request(
           ^^^^^^^^^^^^^^^^^^^
  File "/home/container/.local/lib/python3.12/site-packages/aiohttp/client.py", line 703, in _request
    conn = await self._connector.connect(
           ^^^^^^^^^^^^^^^^^^^^^^^^^^^^^^
  File "/home/container/.local/lib/python3.12/site-packages/aiohttp/connector.py", line 548, in connect
    proto = await self._create_connection(req, traces, timeout)
            ^^^^^^^^^^^^^^^^^^^^^^^^^^^^^^^^^^^^^^^^^^^^^^^^^^^
  File "/home/container/.local/lib/python3.12/site-packages/aiohttp/connector.py", line 1056, in _create_connection
    _, proto = await self._create_direct_connection(req, traces, timeout)
               ^^^^^^^^^^^^^^^^^^^^^^^^^^^^^^^^^^^^^^^^^^^^^^^^^^^^^^^^^^
  File "/home/container/.local/lib/python3.12/site-packages/aiohttp/connector.py", line 1357, in _create_direct_connection
    raise ClientConnectorDNSError(req.connection_key, exc) from exc
aiohttp.client_exceptions.ClientConnectorDNSError: Cannot connect to host gateway-us-east1-c.discord.gg:443 ssl:default [Temporary failure in name resolution]
2025-01-12 19:54:11,087 - INFO - Shard ID None session has been invalidated.
2025-01-12 19:54:16,724 - INFO - Shard ID None has connected to Gateway (Session ID: b7ec2792e76b2063c7a3247ace2eeb14).
2025-01-12 19:54:34,548 - WARNING - Shard ID 0 timed out waiting for chunks for guild_id 1123960532463014001.
2025-01-12 19:54:39,688 - ERROR - Ignoring exception in cog unload for Cog <class 'cogs.sticky.StickyBot'> ('StickyBot')
Traceback (most recent call last):
  File "/home/container/.local/lib/python3.12/site-packages/discord/ext/commands/cog.py", line 776, in _eject
    await maybe_coroutine(self.cog_unload)
  File "/home/container/.local/lib/python3.12/site-packages/discord/utils.py", line 694, in maybe_coroutine
    return await value
           ^^^^^^^^^^^
  File "/home/container/cogs/sticky.py", line 191, in cog_unload
    await self.sticky_task
TypeError: object Loop can't be used in 'await' expression
2025-01-12 20:06:09,855 - ERROR - Ignoring exception in command None
discord.ext.commands.errors.CommandNotFound: Command "/gcreate" is not found
2025-01-12 20:06:09,866 - ERROR - Ignoring exception in command None
discord.ext.commands.errors.CommandNotFound: Command "/gcreate" is not found
2025-01-12 20:26:09,504 - ERROR - Ignoring exception in command None
discord.ext.commands.errors.CommandNotFound: Command "." is not found
2025-01-12 20:48:07,379 - WARNING - Can't keep up, shard ID None websocket is 42.5s behind.
2025-01-12 21:51:30,569 - WARNING - Can't keep up, shard ID None websocket is 45.5s behind.
2025-01-12 21:53:39,500 - ERROR - Ignoring exception in command None
discord.ext.commands.errors.CommandNotFound: Command ".." is not found
2025-01-12 21:53:39,666 - ERROR - Ignoring exception in command None
discord.ext.commands.errors.CommandNotFound: Command ".." is not found
2025-01-12 22:00:52,934 - INFO - Shard ID None has successfully RESUMED session b7ec2792e76b2063c7a3247ace2eeb14.
2025-01-12 22:39:05,272 - ERROR - Ignoring exception in command None
discord.ext.commands.errors.CommandNotFound: Command "gg/gayyyy" is not found
2025-01-13 00:14:21,012 - ERROR - Ignoring exception in command None
discord.ext.commands.errors.CommandNotFound: Command "." is not found
2025-01-13 00:14:22,065 - ERROR - Ignoring exception in command None
discord.ext.commands.errors.CommandNotFound: Command ".." is not found
2025-01-13 00:14:23,943 - ERROR - Ignoring exception in command None
discord.ext.commands.errors.CommandNotFound: Command "..." is not found
2025-01-13 01:44:37,719 - INFO - Shard ID None has successfully RESUMED session b7ec2792e76b2063c7a3247ace2eeb14.
2025-01-13 02:39:17,093 - INFO - Shard ID None has successfully RESUMED session b7ec2792e76b2063c7a3247ace2eeb14.
2025-01-13 02:41:22,692 - ERROR - Ignoring exception in command None
discord.ext.commands.errors.CommandNotFound: Command "........ill" is not found
2025-01-13 02:41:22,694 - ERROR - Ignoring exception in command None
discord.ext.commands.errors.CommandNotFound: Command "........ill" is not found
2025-01-13 02:46:21,886 - ERROR - Ignoring exception in on_message
Traceback (most recent call last):
  File "/home/container/.local/lib/python3.12/site-packages/discord/client.py", line 449, in _run_event
    await coro(*args, **kwargs)
  File "/home/container/cogs/afk_cog.py", line 109, in on_message
    time_diff = datetime.utcnow() - timestamp
                ~~~~~~~~~~~~~~~~~~^~~~~~~~~~~
TypeError: unsupported operand type(s) for -: 'datetime.datetime' and 'str'
2025-01-13 02:56:05,227 - WARNING - Shard ID None has stopped responding to the gateway. Closing and restarting.
2025-01-13 02:56:17,457 - INFO - Shard ID None has successfully RESUMED session b7ec2792e76b2063c7a3247ace2eeb14.
2025-01-13 03:41:07,679 - WARNING - Shard ID None heartbeat blocked for more than 10 seconds.
Loop thread traceback (most recent call last):
  File "/home/container/main.py", line 86, in <module>
    bot.run(DISCORD_TOKEN)
  File "/home/container/.local/lib/python3.12/site-packages/discord/client.py", line 869, in run
    asyncio.run(runner())
  File "/usr/local/lib/python3.12/asyncio/runners.py", line 194, in run
    return runner.run(main)
  File "/usr/local/lib/python3.12/asyncio/runners.py", line 118, in run
    return self._loop.run_until_complete(task)
  File "/usr/local/lib/python3.12/asyncio/base_events.py", line 673, in run_until_complete
    self.run_forever()
  File "/usr/local/lib/python3.12/asyncio/base_events.py", line 640, in run_forever
    self._run_once()
  File "/usr/local/lib/python3.12/asyncio/base_events.py", line 1992, in _run_once
    handle._run()
  File "/usr/local/lib/python3.12/asyncio/events.py", line 88, in _run
    self._context.run(self._callback, *self._args)

2025-01-13 03:41:08,806 - WARNING - Can't keep up, shard ID None websocket is 74.1s behind.
2025-01-13 03:41:40,327 - WARNING - Can't keep up, shard ID None websocket is 28.7s behind.
2025-01-13 05:05:57,769 - ERROR - Ignoring exception in command None
discord.ext.commands.errors.CommandNotFound: Command ".." is not found
2025-01-13 05:05:57,774 - ERROR - Ignoring exception in command None
discord.ext.commands.errors.CommandNotFound: Command ".." is not found
2025-01-13 05:15:55,770 - INFO - Shard ID None has successfully RESUMED session b7ec2792e76b2063c7a3247ace2eeb14.
2025-01-13 06:27:45,957 - ERROR - Ignoring exception in command None
discord.ext.commands.errors.CommandNotFound: Command "." is not found
2025-01-13 06:27:45,960 - ERROR - Ignoring exception in command None
discord.ext.commands.errors.CommandNotFound: Command "." is not found
2025-01-13 06:29:45,515 - ERROR - Ignoring exception in command None
discord.ext.commands.errors.CommandNotFound: Command "..nvm" is not found
2025-01-13 07:25:10,372 - INFO - Shard ID None has successfully RESUMED session b7ec2792e76b2063c7a3247ace2eeb14.
2025-01-13 07:45:42,751 - INFO - Shard ID None has successfully RESUMED session b7ec2792e76b2063c7a3247ace2eeb14.
2025-01-13 07:46:19,776 - INFO - Shard ID None has successfully RESUMED session b7ec2792e76b2063c7a3247ace2eeb14.
2025-01-13 10:01:45,625 - ERROR - Ignoring exception in command None
discord.ext.commands.errors.CommandNotFound: Command ".." is not found
2025-01-13 10:01:45,627 - ERROR - Ignoring exception in command None
discord.ext.commands.errors.CommandNotFound: Command ".." is not found
2025-01-13 10:22:14,719 - INFO - Shard ID None has successfully RESUMED session b7ec2792e76b2063c7a3247ace2eeb14.
2025-01-13 11:54:02,809 - ERROR - Ignoring exception in command None
discord.ext.commands.errors.CommandNotFound: Command "..hm" is not found
2025-01-13 12:47:26,805 - ERROR - Ignoring exception in command None
discord.ext.commands.errors.CommandNotFound: Command ".........." is not found
2025-01-13 12:47:26,807 - ERROR - Ignoring exception in command None
discord.ext.commands.errors.CommandNotFound: Command ".........." is not found
2025-01-13 14:03:38,922 - ERROR - Ignoring exception in on_message
Traceback (most recent call last):
  File "/home/container/.local/lib/python3.12/site-packages/discord/client.py", line 449, in _run_event
    await coro(*args, **kwargs)
  File "/home/container/cogs/thread.py", line 55, in on_message
    thread = await message.create_thread(name=thread_name, auto_archive_duration=1440)
             ^^^^^^^^^^^^^^^^^^^^^^^^^^^^^^^^^^^^^^^^^^^^^^^^^^^^^^^^^^^^^^^^^^^^^^^^^
  File "/home/container/.local/lib/python3.12/site-packages/discord/message.py", line 1407, in create_thread
    data = await self._state.http.start_thread_with_message(
           ^^^^^^^^^^^^^^^^^^^^^^^^^^^^^^^^^^^^^^^^^^^^^^^^^
  File "/home/container/.local/lib/python3.12/site-packages/discord/http.py", line 758, in request
    raise HTTPException(response, data)
discord.errors.HTTPException: 400 Bad Request (error code: 10008): Unknown Message
2025-01-13 14:11:37,294 - INFO - Shard ID None has successfully RESUMED session b7ec2792e76b2063c7a3247ace2eeb14.
2025-01-13 14:53:49,848 - INFO - Shard ID None has successfully RESUMED session b7ec2792e76b2063c7a3247ace2eeb14.
2025-01-13 14:58:39,580 - ERROR - Ignoring exception in command None
discord.ext.commands.errors.CommandNotFound: Command "0." is not found
2025-01-13 15:09:03,674 - ERROR - Ignoring exception in command None
discord.ext.commands.errors.CommandNotFound: Command "." is not found
2025-01-13 16:00:01,744 - INFO - Shard ID None has successfully RESUMED session b7ec2792e76b2063c7a3247ace2eeb14.
2025-01-13 16:25:31,548 - ERROR - Ignoring exception in command None
discord.ext.commands.errors.CommandNotFound: Command ".." is not found
2025-01-13 16:25:31,549 - ERROR - Ignoring exception in command None
discord.ext.commands.errors.CommandNotFound: Command ".." is not found
2025-01-13 16:30:05,682 - INFO - Shard ID None has successfully RESUMED session b7ec2792e76b2063c7a3247ace2eeb14.
2025-01-13 16:56:26,745 - ERROR - Ignoring exception in command None
discord.ext.commands.errors.CommandNotFound: Command ".." is not found
2025-01-13 16:56:26,751 - ERROR - Ignoring exception in command None
discord.ext.commands.errors.CommandNotFound: Command ".." is not found
2025-01-13 17:22:22,905 - ERROR - Ignoring exception in command None
discord.ext.commands.errors.CommandNotFound: Command "." is not found
2025-01-13 17:29:20,465 - WARNING - Can't keep up, shard ID None websocket is 43.2s behind.
2025-01-13 18:11:24,687 - ERROR - Attempting a reconnect in 0.78s
Traceback (most recent call last):
  File "/home/container/.local/lib/python3.12/site-packages/discord/client.py", line 667, in connect
    await self.ws.poll_event()
  File "/home/container/.local/lib/python3.12/site-packages/discord/gateway.py", line 625, in poll_event
    await self.received_message(msg.data)
  File "/home/container/.local/lib/python3.12/site-packages/discord/gateway.py", line 533, in received_message
    await self.send_as_json(beat)
  File "/home/container/.local/lib/python3.12/site-packages/discord/gateway.py", line 661, in send_as_json
    await self.send(utils._to_json(data))
  File "/home/container/.local/lib/python3.12/site-packages/discord/gateway.py", line 657, in send
    await self.socket.send_str(data)
  File "/home/container/.local/lib/python3.12/site-packages/aiohttp/client_ws.py", line 243, in send_str
    await self._writer.send_frame(
  File "/home/container/.local/lib/python3.12/site-packages/aiohttp/_websocket/writer.py", line 125, in send_frame
    raise ClientConnectionResetError("Cannot write to closing transport")
aiohttp.client_exceptions.ClientConnectionResetError: Cannot write to closing transport
2025-01-13 18:11:35,610 - INFO - Shard ID None has successfully RESUMED session b7ec2792e76b2063c7a3247ace2eeb14.
2025-01-13 18:59:24,761 - ERROR - Ignoring exception in command None
discord.ext.commands.errors.CommandNotFound: Command "+" is not found
2025-01-13 18:59:24,763 - ERROR - Ignoring exception in command None
discord.ext.commands.errors.CommandNotFound: Command "+" is not found
2025-01-13 19:03:25,195 - ERROR - Ignoring exception in command None
discord.ext.commands.errors.CommandNotFound: Command ".." is not found
2025-01-13 19:03:25,198 - ERROR - Ignoring exception in command None
discord.ext.commands.errors.CommandNotFound: Command ".." is not found
2025-01-13 19:13:04,750 - ERROR - Ignoring exception in command None
discord.ext.commands.errors.CommandNotFound: Command "_." is not found
2025-01-13 19:13:04,752 - ERROR - Ignoring exception in command None
discord.ext.commands.errors.CommandNotFound: Command "_." is not found
2025-01-13 19:22:39,686 - ERROR - Ignoring exception in command None
discord.ext.commands.errors.CommandNotFound: Command "..." is not found
2025-01-13 19:22:39,688 - ERROR - Ignoring exception in command None
discord.ext.commands.errors.CommandNotFound: Command "..." is not found
2025-01-13 19:33:16,658 - INFO - Shard ID None has successfully RESUMED session b7ec2792e76b2063c7a3247ace2eeb14.
2025-01-13 19:40:15,095 - ERROR - Ignoring exception in command None
discord.ext.commands.errors.CommandNotFound: Command ".." is not found
2025-01-13 20:05:24,105 - ERROR - Ignoring exception in command None
discord.ext.commands.errors.CommandNotFound: Command "." is not found
2025-01-13 20:05:24,130 - ERROR - Ignoring exception in command None
discord.ext.commands.errors.CommandNotFound: Command "." is not found
2025-01-13 20:11:14,547 - ERROR - Ignoring exception in command None
discord.ext.commands.errors.CommandNotFound: Command "ai" is not found
2025-01-13 20:17:21,175 - ERROR - Ignoring exception in command None
discord.ext.commands.errors.CommandNotFound: Command "." is not found
2025-01-13 20:17:21,176 - ERROR - Ignoring exception in command None
discord.ext.commands.errors.CommandNotFound: Command "." is not found
2025-01-13 20:55:23,415 - INFO - Shard ID None has successfully RESUMED session b7ec2792e76b2063c7a3247ace2eeb14.
2025-01-13 21:41:04,884 - WARNING - Shard ID None has stopped responding to the gateway. Closing and restarting.
2025-01-13 21:41:06,400 - ERROR - Attempting a reconnect in 1.99s
Traceback (most recent call last):
  File "/home/container/.local/lib/python3.12/site-packages/discord/client.py", line 667, in connect
    await self.ws.poll_event()
  File "/home/container/.local/lib/python3.12/site-packages/discord/gateway.py", line 625, in poll_event
    await self.received_message(msg.data)
  File "/home/container/.local/lib/python3.12/site-packages/discord/gateway.py", line 533, in received_message
    await self.send_as_json(beat)
  File "/home/container/.local/lib/python3.12/site-packages/discord/gateway.py", line 661, in send_as_json
    await self.send(utils._to_json(data))
  File "/home/container/.local/lib/python3.12/site-packages/discord/gateway.py", line 657, in send
    await self.socket.send_str(data)
  File "/home/container/.local/lib/python3.12/site-packages/aiohttp/client_ws.py", line 243, in send_str
    await self._writer.send_frame(
  File "/home/container/.local/lib/python3.12/site-packages/aiohttp/_websocket/writer.py", line 125, in send_frame
    raise ClientConnectionResetError("Cannot write to closing transport")
aiohttp.client_exceptions.ClientConnectionResetError: Cannot write to closing transport
2025-01-13 21:41:13,142 - INFO - Shard ID None has successfully RESUMED session b7ec2792e76b2063c7a3247ace2eeb14.
2025-01-13 21:43:10,402 - ERROR - Ignoring exception in command None
discord.ext.commands.errors.CommandNotFound: Command "." is not found
2025-01-13 21:43:10,414 - ERROR - Ignoring exception in command None
discord.ext.commands.errors.CommandNotFound: Command "." is not found
2025-01-13 21:43:22,724 - ERROR - Ignoring exception in command None
discord.ext.commands.errors.CommandNotFound: Command ".." is not found
2025-01-13 21:43:22,735 - ERROR - Ignoring exception in command None
discord.ext.commands.errors.CommandNotFound: Command ".." is not found
2025-01-13 21:47:48,624 - INFO - Shard ID None has successfully RESUMED session b7ec2792e76b2063c7a3247ace2eeb14.
2025-01-13 21:50:15,416 - ERROR - Ignoring exception in command None
discord.ext.commands.errors.CommandNotFound: Command "..to" is not found
2025-01-13 21:50:15,493 - ERROR - Ignoring exception in command None
discord.ext.commands.errors.CommandNotFound: Command "..to" is not found
2025-01-13 23:17:56,065 - ERROR - Attempting a reconnect in 1.77s
Traceback (most recent call last):
  File "/home/container/.local/lib/python3.12/site-packages/discord/client.py", line 667, in connect
    await self.ws.poll_event()
  File "/home/container/.local/lib/python3.12/site-packages/discord/gateway.py", line 625, in poll_event
    await self.received_message(msg.data)
  File "/home/container/.local/lib/python3.12/site-packages/discord/gateway.py", line 533, in received_message
    await self.send_as_json(beat)
  File "/home/container/.local/lib/python3.12/site-packages/discord/gateway.py", line 661, in send_as_json
    await self.send(utils._to_json(data))
  File "/home/container/.local/lib/python3.12/site-packages/discord/gateway.py", line 657, in send
    await self.socket.send_str(data)
  File "/home/container/.local/lib/python3.12/site-packages/aiohttp/client_ws.py", line 243, in send_str
    await self._writer.send_frame(
  File "/home/container/.local/lib/python3.12/site-packages/aiohttp/_websocket/writer.py", line 125, in send_frame
    raise ClientConnectionResetError("Cannot write to closing transport")
aiohttp.client_exceptions.ClientConnectionResetError: Cannot write to closing transport
2025-01-13 23:18:01,964 - INFO - Shard ID None has successfully RESUMED session b7ec2792e76b2063c7a3247ace2eeb14.
